<robot name="iCub">
    <link name="root_link">
        <inertial>
            <origin xyz="0.0248821 0.000103947 -0.0440806"
                    rpy="1.57079632679 0 -1.57079632679"/>
            <mass value="5.09143"/>
            <inertia ixx="0.0139679" ixy="-5.93488e-06" ixz="-1.55458e-05" iyy="0.0202112"
                     iyz="-0.00170968" izz="0.0249124"/>
        </inertial>
        <visual>
            <origin xyz="-0.0364 0 0.032" rpy="1.57079632679 0 -1.57079632679"/>
            <geometry>
                <mesh filename="package://iCub/meshes/simmechanics/sim_sea_2-5_root_link_prt-binary.stl"
                      scale="0.001 0.001 0.001"/>
            </geometry>
            <material name="green">
                <color rgba="0 1 0 1"/>
            </material>
        </visual>
        <collision>
            <origin xyz="-0.0364 0 0.032" rpy="1.57079632679 0 -1.57079632679"/>
            <geometry>
                <mesh filename="package://iCub/meshes/simmechanics/sim_sea_2-5_root_link_prt-binary.stl"
                      scale="0.001 0.001 0.001"/>
            </geometry>
        </collision>
    </link>
    <link name="r_hip_1">
        <inertial>
            <origin xyz="-0.0005145 -0.0380753 -7.1e-05"
                    rpy="1.57079632679 0 1.57079632679"/>
            <mass value="0.919978"/>
            <inertia ixx="0.000404268" ixy="-1.26852e-06" ixz="1.11055e-06"
                     iyy="0.000574741" iyz="-7.69474e-07" izz="0.000580025"/>
        </inertial>
        <visual>
            <origin xyz="0.0428515000001 0.026 0.151913"
                    rpy="1.57079632679 0 1.57079632679"/>
            <geometry>
                <mesh filename="package://iCub/meshes/simmechanics/sim_sea_2-5_r_hip_1_prt-binary.stl"
                      scale="0.001 0.001 0.001"/>
            </geometry>
            <material name="black">
                <color rgba="0 0 0 1"/>
            </material>
        </visual>
        <collision>
            <origin xyz="0.0428515000001 0.026 0.151913"
                    rpy="1.57079632679 0 1.57079632679"/>
            <geometry>
                <mesh filename="package://iCub/meshes/simmechanics/sim_sea_2-5_r_hip_1_prt-binary.stl"
                      scale="0.001 0.001 0.001"/>
            </geometry>
        </collision>
    </link>
    <joint name="r_hip_pitch" type="revolute">
        <origin xyz="0.0064515 0.026 -0.119913" rpy="0 0 -3.14159265359"/>
        <axis xyz="-2.22044604925e-16 -1.0 0.0"/>
        <parent link="root_link"/>
        <child link="r_hip_1"/>
        <limit effort="55.5" lower="-0.785398163397" upper="2.33874119767"
               velocity="5.1"/>
        <dynamics damping="1.0" friction="0.0"/>
    </joint>
    <link name="r_hip_2">
        <inertial>
            <origin xyz="-0.0009315 8.09999999998e-06 -0.044809"
                    rpy="1.57079632679 0 1.57079632679"/>
            <mass value="0.413242"/>
            <inertia ixx="0.00046914" ixy="-4.76597e-08" ixz="7.12496e-08"
                     iyy="0.000277108" iyz="3.3401e-06" izz="0.000303891"/>
        </inertial>
        <visual>
            <origin xyz="0.0428514998094 0.0701 0.151913"
                    rpy="1.57079632679 0 1.57079632679"/>
            <geometry>
                <mesh filename="package://iCub/meshes/simmechanics/sim_sea_2-5_r_hip_2_prt-binary.stl"
                      scale="0.001 0.001 0.001"/>
            </geometry>
            <material name="red">
                <color rgba="1 0 0 1"/>
            </material>
        </visual>
        <collision>
            <origin xyz="0.0428514998094 0.0701 0.151913"
                    rpy="1.57079632679 0 1.57079632679"/>
            <geometry>
                <mesh filename="package://iCub/meshes/simmechanics/sim_sea_2-5_r_hip_2_prt-binary.stl"
                      scale="0.001 0.001 0.001"/>
            </geometry>
        </collision>
    </link>
    <joint name="r_hip_roll" type="revolute">
        <origin xyz="0 -0.0441 0" rpy="0 0 0"/>
        <axis xyz="-1.0 0.0 -2.22044604925e-16"/>
        <parent link="r_hip_1"/>
        <child link="r_hip_2"/>
        <limit effort="37.0" lower="-0.349065850399" upper="2.09439510239"
               velocity="7.64"/>
        <dynamics damping="1.0" friction="0.0"/>
    </joint>
    <link name="r_hip_3">
        <inertial>
            <origin xyz="-0.000123 -0.0002823 0.008718"
                    rpy="-1.57079632679 0 -1.57079632679"/>
            <mass value="0.126212"/>
            <inertia ixx="0.01" ixy="2.67901e-07" ixz="-4.41463e-09" iyy="0.01"
                     iyz="3.32338e-08" izz="0.01"/>
        </inertial>
        <visual>
            <origin xyz="0.0437090152 -0.0700999919 -0.226213"
                    rpy="-1.57079632679 0 -1.57079632679"/>
            <geometry>
                <mesh filename="package://iCub/meshes/simmechanics/sim_sea_2-5_r_upper_thigh_prt-binary.stl"
                      scale="0.001 0.001 0.001"/>
            </geometry>
            <material name="blue">
                <color rgba="0 0 1 1"/>
            </material>
        </visual>
        <collision>
            <origin xyz="0.0437090152 -0.0700999919 -0.226213"
                    rpy="-1.57079632679 0 -1.57079632679"/>
            <geometry>
                <mesh filename="package://iCub/meshes/simmechanics/sim_sea_2-5_r_upper_thigh_prt-binary.stl"
                      scale="0.001 0.001 0.001"/>
            </geometry>
        </collision>
    </link>
    <joint name="r_leg_ft_sensor" type="fixed">
        <origin xyz="-0.0009363 1.39e-05 -0.0743" rpy="3.14159265359 0 0"/>
        <parent link="r_hip_2"/>
        <child link="r_hip_3"/>
        <dynamics damping="0.1"/>
    </joint>
    <link name="r_upper_leg">
        <inertial>
            <origin xyz="0.0034 -2.91e-05 -0.078954" rpy="1.57079632679 0 1.57079632679"/>
            <mass value="1.8035"/>
            <inertia ixx="0.00647751422999" ixy="0.000129579429588"
                     ixz="5.48205094739e-06" iyy="0.0014593786411"
                     iyz="-0.000136613086875" izz="0.00646720823813"/>
        </inertial>
        <visual>
            <origin xyz="0.0437090152 0.0700999919 0.240813"
                    rpy="1.57079632679 0 1.57079632679"/>
            <geometry>
                <mesh filename="package://iCub/meshes/simmechanics/sim_sea_2-5_r_thigh_prt-binary.stl"
                      scale="0.001 0.001 0.001"/>
            </geometry>
            <material name="yellow">
                <color rgba="1 1 0 1"/>
            </material>
        </visual>
        <collision>
            <origin xyz="0.0437090152 0.0700999919 0.240813"
                    rpy="1.57079632679 0 1.57079632679"/>
            <geometry>
                <mesh filename="package://iCub/meshes/simmechanics/sim_sea_2-5_r_thigh_prt-binary.stl"
                      scale="0.001 0.001 0.001"/>
            </geometry>
        </collision>
    </link>
    <joint name="r_hip_yaw" type="revolute">
        <origin xyz="0 0 0.0144" rpy="-3.14159265359 0 0"/>
        <axis xyz="0.0 -2.22044604925e-16 -1.0"/>
        <parent link="r_hip_3"/>
        <child link="r_upper_leg"/>
        <limit effort="37.0" lower="-1.3962634016" upper="1.3962634016" velocity="7.64"/>
        <dynamics damping="1.0" friction="0.0"/>
    </joint>
    <link name="r_upper_leg_back_contact"/>
    <joint name="r_upper_leg_back_contact_fixed_joint" type="fixed">
        <origin xyz="-0.0511998 0 0.0146" rpy="0 1.57079632679 0"/>
        <parent link="r_upper_leg"/>
        <child link="r_upper_leg_back_contact"/>
        <dynamics damping="0.1"/>
    </joint>
    <link name="r_upper_leg_dh_frame"/>
    <joint name="r_upper_leg_dh_frame_fixed_joint" type="fixed">
        <origin xyz="0 0 -0.145825" rpy="1.57079632679 0 0"/>
        <parent link="r_upper_leg"/>
        <child link="r_upper_leg_dh_frame"/>
        <dynamics damping="0.1"/>
    </joint>
    <link name="r_lower_leg">
        <inertial>
            <origin xyz="0.0012364 -0.0035131 -0.088794"
                    rpy="1.57079632679 0 1.57079632679"/>
            <mass value="1.472"/>
            <inertia ixx="0.00423993167478" ixy="0.000228814548854"
                     ixz="-5.55646459453e-05" iyy="0.00152095043447"
                     iyz="-0.000264132979243" izz="0.00457358584206"/>
        </inertial>
        <visual>
            <origin xyz="0.0437090152 0.070099992 0.386638"
                    rpy="1.57079632679 0 1.57079632679"/>
            <geometry>
                <mesh filename="package://iCub/meshes/simmechanics/sim_sea_2-5_r_shank_prt-binary.stl"
                      scale="0.001 0.001 0.001"/>
            </geometry>
            <material name="pink">
                <color rgba="1 0 1 1"/>
            </material>
        </visual>
        <collision>
            <origin xyz="0.0437090152 0.070099992 0.386638"
                    rpy="1.57079632679 0 1.57079632679"/>
            <geometry>
                <mesh filename="package://iCub/meshes/simmechanics/sim_sea_2-5_r_shank_prt-binary.stl"
                      scale="0.001 0.001 0.001"/>
            </geometry>
        </collision>
    </link>
    <joint name="r_knee" type="revolute">
        <origin xyz="0 0 -0.145825" rpy="0 0 0"/>
        <axis xyz="-2.22044604925e-16 -1.0 0.0"/>
        <parent link="r_upper_leg"/>
        <child link="r_lower_leg"/>
        <limit effort="37.0" lower="-2.16420827247" upper="0.0698131700798"
               velocity="7.64"/>
        <dynamics damping="1.0" friction="0.0"/>
    </joint>
    <link name="r_lower_leg_skin_0"/>
    <joint name="r_lower_leg_skin_0_fixed_joint" type="fixed">
        <origin xyz="0.0544117 -0.0312149 -0.002634"
                rpy="2.09173809157e-06 -1.41530676247 2.48648458622"/>
        <parent link="r_lower_leg"/>
        <child link="r_lower_leg_skin_0"/>
        <dynamics damping="0.1"/>
    </joint>
    <link name="r_lower_leg_skin_3"/>
    <joint name="r_lower_leg_skin_3_fixed_joint" type="fixed">
        <origin xyz="0.05157879 0.0304205 -0.002843"
                rpy="0 -1.42951054083 -2.30391484186"/>
        <parent link="r_lower_leg"/>
        <child link="r_lower_leg_skin_3"/>
        <dynamics damping="0.1"/>
    </joint>
    <link name="r_lower_leg_skin_4"/>
    <joint name="r_lower_leg_skin_4_fixed_joint" type="fixed">
        <origin xyz="0.0583103 0.0167836 0.007272"
                rpy="-2.98636361519e-07 -1.25636748876 -2.75892380087"/>
        <parent link="r_lower_leg"/>
        <child link="r_lower_leg_skin_4"/>
        <dynamics damping="0.1"/>
    </joint>
    <link name="r_lower_leg_skin_5"/>
    <joint name="r_lower_leg_skin_5_fixed_joint" type="fixed">
        <origin xyz="0.0636504 0.0003094 -0.001972"
                rpy="0 -1.38652215068 -3.14147169807"/>
        <parent link="r_lower_leg"/>
        <child link="r_lower_leg_skin_5"/>
        <dynamics damping="0.1"/>
    </joint>
    <link name="r_lower_leg_skin_6"/>
    <joint name="r_lower_leg_skin_6_fixed_joint" type="fixed">
        <origin xyz="0.05208554 0.0304434 -0.022149"
                rpy="-3.14158927953 -1.46785123411 0.837492889077"/>
        <parent link="r_lower_leg"/>
        <child link="r_lower_leg_skin_6"/>
        <dynamics damping="0.1"/>
    </joint>
    <link name="r_lower_leg_skin_9"/>
    <joint name="r_lower_leg_skin_9_fixed_joint" type="fixed">
        <origin xyz="0.0598214 0.0167972 -0.030962"
                rpy="-3.14159202356 -1.34224755325 0.379294477718"/>
        <parent link="r_lower_leg"/>
        <child link="r_lower_leg_skin_9"/>
        <dynamics damping="0.1"/>
    </joint>
    <link name="r_lower_leg_skin_10"/>
    <joint name="r_lower_leg_skin_10_fixed_joint" type="fixed">
        <origin xyz="0.0644607 0.0003424 -0.021205"
                rpy="3.14159265355 -1.47095803541 0.000430021675261"/>
        <parent link="r_lower_leg"/>
        <child link="r_lower_leg_skin_10"/>
        <dynamics damping="0.1"/>
    </joint>
    <link name="r_lower_leg_skin_11"/>
    <joint name="r_lower_leg_skin_11_fixed_joint" type="fixed">
        <origin xyz="0.0607108 -0.0160916 -0.030885"
                rpy="-3.14159218252 -1.3281180406 -0.27213836788"/>
        <parent link="r_lower_leg"/>
        <child link="r_lower_leg_skin_11"/>
        <dynamics damping="0.1"/>
    </joint>
    <link name="r_lower_leg_skin_14"/>
    <joint name="r_lower_leg_skin_14_fixed_joint" type="fixed">
        <origin xyz="0.0550477 -0.0311759 -0.0219"
                rpy="-3.14159181885 -1.46502735635 -0.654033407167"/>
        <parent link="r_lower_leg"/>
        <child link="r_lower_leg_skin_14"/>
        <dynamics damping="0.1"/>
    </joint>
    <link name="r_lower_leg_skin_15"/>
    <joint name="r_lower_leg_skin_15_fixed_joint" type="fixed">
        <origin xyz="0.0591708 -0.0161788 0.007243"
                rpy="4.27484256729e-07 -1.25203633076 2.86798859471"/>
        <parent link="r_lower_leg"/>
        <child link="r_lower_leg_skin_15"/>
        <dynamics damping="0.1"/>
    </joint>
    <link name="r_lower_leg_skin_16"/>
    <joint name="r_lower_leg_skin_16_fixed_joint" type="fixed">
        <origin xyz="0.0272876 -0.0502869 -0.004549"
                rpy="1.33075915123e-05 -1.53260853515 1.96280242835"/>
        <parent link="r_lower_leg"/>
        <child link="r_lower_leg_skin_16"/>
        <dynamics damping="0.1"/>
    </joint>
    <link name="r_lower_leg_skin_17"/>
    <joint name="r_lower_leg_skin_17_fixed_joint" type="fixed">
        <origin xyz="0.027875 -0.0503119 -0.023882"
                rpy="-3.1415645262 -1.56366240237 -1.18022508756"/>
        <parent link="r_lower_leg"/>
        <child link="r_lower_leg_skin_17"/>
        <dynamics damping="0.1"/>
    </joint>
    <link name="r_lower_leg_skin_19"/>
    <joint name="r_lower_leg_skin_19_fixed_joint" type="fixed">
        <origin xyz="0.03575341 0.0410628 0.006065"
                rpy="-8.90877717426e-07 -1.43498696978 -2.15863618017"/>
        <parent link="r_lower_leg"/>
        <child link="r_lower_leg_skin_19"/>
        <dynamics damping="0.1"/>
    </joint>
    <link name="r_lower_leg_skin_20"/>
    <joint name="r_lower_leg_skin_20_fixed_joint" type="fixed">
        <origin xyz="0.0234419 0.0479908 -0.004952"
                rpy="-3.20556549428e-06 -1.50015513031 -1.86755092413"/>
        <parent link="r_lower_leg"/>
        <child link="r_lower_leg_skin_20"/>
        <dynamics damping="0.1"/>
    </joint>
    <link name="r_lower_leg_skin_21"/>
    <joint name="r_lower_leg_skin_21_fixed_joint" type="fixed">
        <origin xyz="0.0242704 0.0485378 -0.024277"
                rpy="2.29671149558e-05 -1.55545513881 -1.87411972316"/>
        <parent link="r_lower_leg"/>
        <child link="r_lower_leg_skin_21"/>
        <dynamics damping="0.1"/>
    </joint>
    <link name="r_lower_leg_skin_28"/>
    <joint name="r_lower_leg_skin_28_fixed_joint" type="fixed">
        <origin xyz="0.04087216 -0.0424399 -0.032756"
                rpy="3.14158088865 -1.52252462169 -0.929681029763"/>
        <parent link="r_lower_leg"/>
        <child link="r_lower_leg_skin_28"/>
        <dynamics damping="0.1"/>
    </joint>
    <link name="r_lower_leg_skin_29"/>
    <joint name="r_lower_leg_skin_29_fixed_joint" type="fixed">
        <origin xyz="0.03846638 -0.0435159 -0.05242"
                rpy="3.14158017044 -1.53429841563 -0.915436346631"/>
        <parent link="r_lower_leg"/>
        <child link="r_lower_leg_skin_29"/>
        <dynamics damping="0.1"/>
    </joint>
    <link name="r_lower_leg_skin_31"/>
    <joint name="r_lower_leg_skin_31_fixed_joint" type="fixed">
        <origin xyz="0.0391464 -0.0422709 0.006327"
                rpy="-6.58381747139e-07 -1.4186494462 2.20853032986"/>
        <parent link="r_lower_leg"/>
        <child link="r_lower_leg_skin_31"/>
        <dynamics damping="0.1"/>
    </joint>
    <link name="r_lower_leg_skin_32"/>
    <joint name="r_lower_leg_skin_32_fixed_joint" type="fixed">
        <origin xyz="0.04598303 0.0325847 -0.080733"
                rpy="-3.14159014988 -1.52238289798 0.645940380887"/>
        <parent link="r_lower_leg"/>
        <child link="r_lower_leg_skin_32"/>
        <dynamics damping="0.1"/>
    </joint>
    <link name="r_lower_leg_skin_35"/>
    <joint name="r_lower_leg_skin_35_fixed_joint" type="fixed">
        <origin xyz="0.04774868 -0.0312319 -0.080113"
                rpy="-3.14158668275 -1.51758467332 -0.541532486468"/>
        <parent link="r_lower_leg"/>
        <child link="r_lower_leg_skin_35"/>
        <dynamics damping="0.1"/>
    </joint>
    <link name="r_lower_leg_skin_36"/>
    <joint name="r_lower_leg_skin_36_fixed_joint" type="fixed">
        <origin xyz="0.0532241 -0.0156018 -0.088362"
                rpy="-3.14159034144 -1.51587265281 -0.20740733566"/>
        <parent link="r_lower_leg"/>
        <child link="r_lower_leg_skin_36"/>
        <dynamics damping="0.1"/>
    </joint>
    <link name="r_lower_leg_skin_37"/>
    <joint name="r_lower_leg_skin_37_fixed_joint" type="fixed">
        <origin xyz="0.0552572 0.0009644 -0.078318"
                rpy="-3.14158180452 -1.52318336898 0.00752450583063"/>
        <parent link="r_lower_leg"/>
        <child link="r_lower_leg_skin_37"/>
        <dynamics damping="0.1"/>
    </joint>
    <link name="r_lower_leg_skin_38"/>
    <joint name="r_lower_leg_skin_38_fixed_joint" type="fixed">
        <origin xyz="0.04880469 -0.0312629 -0.060757"
                rpy="3.14158665199 -1.5157299554 -0.54215359959"/>
        <parent link="r_lower_leg"/>
        <child link="r_lower_leg_skin_38"/>
        <dynamics damping="0.1"/>
    </joint>
    <link name="r_lower_leg_skin_41"/>
    <joint name="r_lower_leg_skin_41_fixed_joint" type="fixed">
        <origin xyz="0.0566009 -0.0159129 -0.049854"
                rpy="-3.14159198825 -1.40681343597 -0.248233089413"/>
        <parent link="r_lower_leg"/>
        <child link="r_lower_leg_skin_41"/>
        <dynamics damping="0.1"/>
    </joint>
    <link name="r_lower_leg_skin_42"/>
    <joint name="r_lower_leg_skin_42_fixed_joint" type="fixed">
        <origin xyz="0.0570106 0.0007962 -0.05908"
                rpy="3.14158970239 -1.43524750416 0.00687943651504"/>
        <parent link="r_lower_leg"/>
        <child link="r_lower_leg_skin_42"/>
        <dynamics damping="0.1"/>
    </joint>
    <link name="r_lower_leg_skin_43"/>
    <joint name="r_lower_leg_skin_43_fixed_joint" type="fixed">
        <origin xyz="0.04712544 0.0323653 -0.061362"
                rpy="-3.14159136621 -1.53843038237 0.624217523667"/>
        <parent link="r_lower_leg"/>
        <child link="r_lower_leg_skin_43"/>
        <dynamics damping="0.1"/>
    </joint>
    <link name="r_lower_leg_skin_46"/>
    <joint name="r_lower_leg_skin_46_fixed_joint" type="fixed">
        <origin xyz="0.0558157 0.0172164 -0.05018"
                rpy="-3.14158987809 -1.42759881603 0.325607710876"/>
        <parent link="r_lower_leg"/>
        <child link="r_lower_leg_skin_46"/>
        <dynamics damping="0.1"/>
    </joint>
    <link name="r_lower_leg_skin_47"/>
    <joint name="r_lower_leg_skin_47_fixed_joint" type="fixed">
        <origin xyz="0.05264165 0.0176388 -0.08886"
                rpy="3.14158963519 -1.51690559406 0.262640425058"/>
        <parent link="r_lower_leg"/>
        <child link="r_lower_leg_skin_47"/>
        <dynamics damping="0.1"/>
    </joint>
    <link name="r_lower_leg_skin_49"/>
    <joint name="r_lower_leg_skin_49_fixed_joint" type="fixed">
        <origin xyz="0.04113139 0.0324385 -0.138859"
                rpy="-3.14158934751 -1.48996135695 0.729763592113"/>
        <parent link="r_lower_leg"/>
        <child link="r_lower_leg_skin_49"/>
        <dynamics damping="0.1"/>
    </joint>
    <link name="r_lower_leg_skin_50"/>
    <joint name="r_lower_leg_skin_50_fixed_joint" type="fixed">
        <origin xyz="0.043016963 0.0325273 -0.119469"
                rpy="3.14159069596 -1.49900732636 0.695784020081"/>
        <parent link="r_lower_leg"/>
        <child link="r_lower_leg_skin_50"/>
        <dynamics damping="0.1"/>
    </joint>
    <link name="r_lower_leg_skin_51"/>
    <joint name="r_lower_leg_skin_51_fixed_joint" type="fixed">
        <origin xyz="0.05141584 0.017759 -0.108206"
                rpy="-3.14158890179 -1.50628475717 0.272079935713"/>
        <parent link="r_lower_leg"/>
        <child link="r_lower_leg_skin_51"/>
        <dynamics damping="0.1"/>
    </joint>
    <link name="r_lower_leg_skin_52"/>
    <joint name="r_lower_leg_skin_52_fixed_joint" type="fixed">
        <origin xyz="0.05299834 0.0012664 -0.116895"
                rpy="-3.14159164042 -1.50318674421 0.0108717260994"/>
        <parent link="r_lower_leg"/>
        <child link="r_lower_leg_skin_52"/>
        <dynamics damping="0.1"/>
    </joint>
    <link name="r_lower_leg_skin_53"/>
    <joint name="r_lower_leg_skin_53_fixed_joint" type="fixed">
        <origin xyz="0.05207314 -0.0154339 -0.107654"
                rpy="3.14159063987 -1.50595307447 -0.211407322892"/>
        <parent link="r_lower_leg"/>
        <child link="r_lower_leg_skin_53"/>
        <dynamics damping="0.1"/>
    </joint>
    <link name="r_lower_leg_skin_54"/>
    <joint name="r_lower_leg_skin_54_fixed_joint" type="fixed">
        <origin xyz="0.0451271 -0.0307489 -0.118787"
                rpy="3.14158825193 -1.49745145571 -0.575115374473"/>
        <parent link="r_lower_leg"/>
        <child link="r_lower_leg_skin_54"/>
        <dynamics damping="0.1"/>
    </joint>
    <link name="r_lower_leg_skin_55"/>
    <joint name="r_lower_leg_skin_55_fixed_joint" type="fixed">
        <origin xyz="0.043502679 -0.0304889 -0.138143"
                rpy="3.14158906486 -1.48995787038 -0.597219943789"/>
        <parent link="r_lower_leg"/>
        <child link="r_lower_leg_skin_55"/>
        <dynamics damping="0.1"/>
    </joint>
    <link name="r_lower_leg_skin_56"/>
    <joint name="r_lower_leg_skin_56_fixed_joint" type="fixed">
        <origin xyz="0.04926841 -0.015121 -0.146218"
                rpy="-3.14158920404 -1.49124819828 -0.2234844764"/>
        <parent link="r_lower_leg"/>
        <child link="r_lower_leg_skin_56"/>
        <dynamics damping="0.1"/>
    </joint>
    <link name="r_lower_leg_skin_60"/>
    <joint name="r_lower_leg_skin_60_fixed_joint" type="fixed">
        <origin xyz="0.04836968 0.018056 -0.146938"
                rpy="-3.14159173337 -1.48985968527 0.302951871954"/>
        <parent link="r_lower_leg"/>
        <child link="r_lower_leg_skin_60"/>
        <dynamics damping="0.1"/>
    </joint>
    <link name="r_lower_leg_skin_61"/>
    <joint name="r_lower_leg_skin_61_fixed_joint" type="fixed">
        <origin xyz="0.05161954 0.0014266 -0.136169"
                rpy="-3.14159100925 -1.49602097086 0.0132014275205"/>
        <parent link="r_lower_leg"/>
        <child link="r_lower_leg_skin_61"/>
        <dynamics damping="0.1"/>
    </joint>
    <link name="r_ankle_1">
        <inertial>
            <origin xyz="0.0151436 -0.0008686 4.2e-05"
                    rpy="1.57079632679 0 1.57079632679"/>
            <mass value="0.6803"/>
            <inertia ixx="0.000404618848932" ixy="7.49819286945e-07"
                     ixz="-3.01349467691e-05" iyy="0.000448633654664"
                     iyz="2.5726697409e-06" izz="0.000308235939139"/>
        </inertial>
        <visual>
            <origin xyz="0.0437090152 0.070099992 0.587138"
                    rpy="1.57079632679 0 1.57079632679"/>
            <geometry>
                <mesh filename="package://iCub/meshes/simmechanics/sim_sea_2-5_r_ankle_prt-binary.stl"
                      scale="0.001 0.001 0.001"/>
            </geometry>
            <material name="cyan">
                <color rgba="0 1 1 1"/>
            </material>
        </visual>
        <collision>
            <origin xyz="0.0437090152 0.070099992 0.587138"
                    rpy="1.57079632679 0 1.57079632679"/>
            <geometry>
                <mesh filename="package://iCub/meshes/simmechanics/sim_sea_2-5_r_ankle_prt-binary.stl"
                      scale="0.001 0.001 0.001"/>
            </geometry>
        </collision>
    </link>
    <joint name="r_ankle_pitch" type="revolute">
        <origin xyz="0 0 -0.2005" rpy="0 0 0"/>
        <axis xyz="2.22044604925e-16 1.0 0.0"/>
        <parent link="r_lower_leg"/>
        <child link="r_ankle_1"/>
        <limit effort="37.0" lower="-0.610865238198" upper="0.610865238198"
               velocity="7.64"/>
        <dynamics damping="1.0" friction="0.0"/>
    </joint>
    <link name="r_ankle_2">
        <inertial>
            <origin xyz="0.0011446 3.59999999999e-06 -0.03852"
                    rpy="1.57079632679 0 1.57079632679"/>
            <mass value="0.265122"/>
            <inertia ixx="0.01" ixy="-4.74606e-08" ixz="4.94571e-08" iyy="0.01"
                     iyz="-4.29975e-06" izz="0.01"/>
        </inertial>
        <visual>
            <origin xyz="0.0437877996186 0.0700861001907 0.587138"
                    rpy="1.57079632679 0 1.57079632679"/>
            <geometry>
                <mesh filename="package://iCub/meshes/simmechanics/sim_sea_2-5_r_foot_prt-binary.stl"
                      scale="0.001 0.001 0.001"/>
            </geometry>
            <material name="green">
                <color rgba="0 1 0 1"/>
            </material>
        </visual>
        <collision>
            <origin xyz="0.0437877996186 0.0700861001907 0.587138"
                    rpy="1.57079632679 0 1.57079632679"/>
            <geometry>
                <mesh filename="package://iCub/meshes/simmechanics/sim_sea_2-5_r_foot_prt-binary.stl"
                      scale="0.001 0.001 0.001"/>
            </geometry>
        </collision>
    </link>
    <joint name="r_ankle_roll" type="revolute">
        <origin xyz="0 0 0" rpy="0 0 0"/>
        <axis xyz="-1.0 0.0 -2.22044604925e-16"/>
        <parent link="r_ankle_1"/>
        <child link="r_ankle_2"/>
        <limit effort="37.0" lower="-0.436332312999" upper="0.436332312999"
               velocity="7.64"/>
        <dynamics damping="1.0" friction="0.0"/>
    </joint>
    <link name="r_foot">
        <inertial>
            <origin xyz="0.0336001 0.0053719 -0.001147"
                    rpy="-1.57079632679 0 -1.57079632679"/>
            <mass value="0.382866"/>
            <inertia ixx="0.00120946" ixy="3.74585e-07" ixz="-5.78759e-05"
                     iyy="0.00141439" iyz="-7.80325e-06" izz="0.000273599"/>
        </inertial>
        <visual>
            <origin xyz="0.047209015 -0.070099992 -0.647438000286"
                    rpy="-1.57079632679 0 -1.57079632679"/>
            <geometry>
                <mesh filename="package://iCub/meshes/simmechanics/sim_sea_2-5_r_sole_prt-binary.stl"
                      scale="0.001 0.001 0.001"/>
            </geometry>
            <material name="white">
                <color rgba="1 1 1 1"/>
            </material>
        </visual>
        <collision>
            <origin xyz="0.03 0.005 0.014" rpy="0.0 0.0 0.0"/>
            <geometry>
                <box size="0.16 0.072 0.001"/>
            </geometry>
        </collision>
    </link>
    <joint name="r_foot_ft_sensor" type="fixed">
        <origin xyz="-0.0035 0 -0.0605" rpy="3.14159265359 0 0"/>
        <parent link="r_ankle_2"/>
        <child link="r_foot"/>
        <dynamics damping="0.1"/>
    </joint>
    <link name="r_sole"/>
    <joint name="r_sole_fixed_joint" type="fixed">
        <origin xyz="0.0035 0 0.004" rpy="-3.14159265359 0 0"/>
        <parent link="r_foot"/>
        <child link="r_sole"/>
        <dynamics damping="0.1"/>
    </joint>
    <link name="r_sole_skin_0"/>
    <joint name="r_sole_skin_0_fixed_joint" type="fixed">
        <origin xyz="0.0604767 -0.0254106 0.0075" rpy="0 0 0"/>
        <parent link="r_foot"/>
        <child link="r_sole_skin_0"/>
        <dynamics damping="0.1"/>
    </joint>
    <link name="r_sole_skin_1"/>
    <joint name="r_sole_skin_1_fixed_joint" type="fixed">
        <origin xyz="0.0788512 -0.0194404 0.0075" rpy="0 0 0"/>
        <parent link="r_foot"/>
        <child link="r_sole_skin_1"/>
        <dynamics damping="0.1"/>
    </joint>
    <link name="r_sole_skin_2"/>
    <joint name="r_sole_skin_2_fixed_joint" type="fixed">
        <origin xyz="0.0932087 -0.032368 0.0075" rpy="0 0 0"/>
        <parent link="r_foot"/>
        <child link="r_sole_skin_2"/>
        <dynamics damping="0.1"/>
    </joint>
    <link name="r_sole_skin_3"/>
    <joint name="r_sole_skin_3_fixed_joint" type="fixed">
        <origin xyz="0.1115831 -0.0263978 0.0075" rpy="0 0 0"/>
        <parent link="r_foot"/>
        <child link="r_sole_skin_3"/>
        <dynamics damping="0.1"/>
    </joint>
    <link name="r_sole_skin_4"/>
    <joint name="r_sole_skin_4_fixed_joint" type="fixed">
        <origin xyz="0.1156 -0.0075 0.0075" rpy="0 0 0"/>
        <parent link="r_foot"/>
        <child link="r_sole_skin_4"/>
        <dynamics damping="0.1"/>
    </joint>
    <link name="r_sole_skin_8"/>
    <joint name="r_sole_skin_8_fixed_joint" type="fixed">
        <origin xyz="0.1052593 0.0243254 0.0075" rpy="0 0 0"/>
        <parent link="r_foot"/>
        <child link="r_sole_skin_8"/>
        <dynamics damping="0.1"/>
    </joint>
    <link name="r_sole_skin_9"/>
    <joint name="r_sole_skin_9_fixed_joint" type="fixed">
        <origin xyz="0.0909017 0.0372529 0.0075" rpy="0 0 0"/>
        <parent link="r_foot"/>
        <child link="r_sole_skin_9"/>
        <dynamics damping="0.1"/>
    </joint>
    <link name="r_sole_skin_10"/>
    <joint name="r_sole_skin_10_fixed_joint" type="fixed">
        <origin xyz="0.0725273 0.0312829 0.0075" rpy="0 0 0"/>
        <parent link="r_foot"/>
        <child link="r_sole_skin_10"/>
        <dynamics damping="0.1"/>
    </joint>
    <link name="r_sole_skin_11"/>
    <joint name="r_sole_skin_11_fixed_joint" type="fixed">
        <origin xyz="0.0685105 0.012385 0.0075" rpy="0 0 0"/>
        <parent link="r_foot"/>
        <child link="r_sole_skin_11"/>
        <dynamics damping="0.1"/>
    </joint>
    <link name="r_sole_skin_12"/>
    <joint name="r_sole_skin_12_fixed_joint" type="fixed">
        <origin xyz="0.082868 -0.0005426 0.0075" rpy="0 0 0"/>
        <parent link="r_foot"/>
        <child link="r_sole_skin_12"/>
        <dynamics damping="0.1"/>
    </joint>
    <link name="r_sole_skin_13"/>
    <joint name="r_sole_skin_13_fixed_joint" type="fixed">
        <origin xyz="0.1012424 0.0054276 0.0075" rpy="0 0 0"/>
        <parent link="r_foot"/>
        <child link="r_sole_skin_13"/>
        <dynamics damping="0.1"/>
    </joint>
    <link name="r_sole_skin_14"/>
    <joint name="r_sole_skin_14_fixed_joint" type="fixed">
        <origin xyz="0.05013604 0.0064148 0.0075" rpy="0 0 0"/>
        <parent link="r_foot"/>
        <child link="r_sole_skin_14"/>
        <dynamics damping="0.1"/>
    </joint>
    <link name="r_sole_skin_15"/>
    <joint name="r_sole_skin_15_fixed_joint" type="fixed">
        <origin xyz="0.04611919 -0.012483 0.0075" rpy="0 0 0"/>
        <parent link="r_foot"/>
        <child link="r_sole_skin_15"/>
        <dynamics damping="0.1"/>
    </joint>
    <link name="r_sole_skin_17"/>
    <joint name="r_sole_skin_17_fixed_joint" type="fixed">
        <origin xyz="-0.0296855 0.0332569 0.0075" rpy="0 0 0"/>
        <parent link="r_foot"/>
        <child link="r_sole_skin_17"/>
        <dynamics damping="0.1"/>
    </joint>
    <link name="r_sole_skin_18"/>
    <joint name="r_sole_skin_18_fixed_joint" type="fixed">
        <origin xyz="-0.0480599 0.027287 0.0075" rpy="0 0 0"/>
        <parent link="r_foot"/>
        <child link="r_sole_skin_18"/>
        <dynamics damping="0.1"/>
    </joint>
    <link name="r_sole_skin_19"/>
    <joint name="r_sole_skin_19_fixed_joint" type="fixed">
        <origin xyz="-0.0520767 0.0083892 0.0075" rpy="0 0 0"/>
        <parent link="r_foot"/>
        <child link="r_sole_skin_19"/>
        <dynamics damping="0.1"/>
    </joint>
    <link name="r_sole_skin_20"/>
    <joint name="r_sole_skin_20_fixed_joint" type="fixed">
        <origin xyz="-0.0377192 -0.0045384 0.0075" rpy="0 0 0"/>
        <parent link="r_foot"/>
        <child link="r_sole_skin_20"/>
        <dynamics damping="0.1"/>
    </joint>
    <link name="r_sole_skin_21"/>
    <joint name="r_sole_skin_21_fixed_joint" type="fixed">
        <origin xyz="0.0357785 0.0193424 0.0075" rpy="0 0 0"/>
        <parent link="r_foot"/>
        <child link="r_sole_skin_21"/>
        <dynamics damping="0.1"/>
    </joint>
    <link name="r_sole_skin_22"/>
    <joint name="r_sole_skin_22_fixed_joint" type="fixed">
        <origin xyz="0.0277448 -0.0184532 0.0075" rpy="0 0 0"/>
        <parent link="r_foot"/>
        <child link="r_sole_skin_22"/>
        <dynamics damping="0.1"/>
    </joint>
    <link name="r_sole_skin_24"/>
    <joint name="r_sole_skin_24_fixed_joint" type="fixed">
        <origin xyz="-0.0049872 -0.0114958 0.0075" rpy="0 0 0"/>
        <parent link="r_foot"/>
        <child link="r_sole_skin_24"/>
        <dynamics damping="0.1"/>
    </joint>
    <link name="r_sole_skin_25"/>
    <joint name="r_sole_skin_25_fixed_joint" type="fixed">
        <origin xyz="0.0133872 -0.0055256 0.0075" rpy="0 0 0"/>
        <parent link="r_foot"/>
        <child link="r_sole_skin_25"/>
        <dynamics damping="0.1"/>
    </joint>
    <link name="r_sole_skin_26"/>
    <joint name="r_sole_skin_26_fixed_joint" type="fixed">
        <origin xyz="0.0174041 0.0133722 0.0075" rpy="0 0 0"/>
        <parent link="r_foot"/>
        <child link="r_sole_skin_26"/>
        <dynamics damping="0.1"/>
    </joint>
    <link name="r_sole_skin_27"/>
    <joint name="r_sole_skin_27_fixed_joint" type="fixed">
        <origin xyz="0.0030465 0.0262998 0.0075" rpy="0 0 0"/>
        <parent link="r_foot"/>
        <child link="r_sole_skin_27"/>
        <dynamics damping="0.1"/>
    </joint>
    <link name="r_sole_skin_28"/>
    <joint name="r_sole_skin_28_fixed_joint" type="fixed">
        <origin xyz="-0.0153279 0.0203296 0.0075" rpy="0 0 0"/>
        <parent link="r_foot"/>
        <child link="r_sole_skin_28"/>
        <dynamics damping="0.1"/>
    </joint>
    <link name="r_sole_skin_29"/>
    <joint name="r_sole_skin_29_fixed_joint" type="fixed">
        <origin xyz="-0.0193448 0.0014318 0.0075" rpy="0 0 0"/>
        <parent link="r_foot"/>
        <child link="r_sole_skin_29"/>
        <dynamics damping="0.1"/>
    </joint>
    <link name="l_hip_1">
        <inertial>
            <origin xyz="-0.0005108 0.0380923 -8.3e-05"
                    rpy="1.57079632679 0 1.57079632679"/>
            <mass value="0.919725"/>
            <inertia ixx="0.000404539" ixy="1.18502e-06" ixz="-9.64514e-07"
                     iyy="0.000573315" iyz="-1.06028e-06" izz="0.000578982"/>
        </inertial>
        <visual>
            <origin xyz="0.0428515000001 -0.026 0.151913"
                    rpy="1.57079632679 0 1.57079632679"/>
            <geometry>
                <mesh filename="package://iCub/meshes/simmechanics/sim_sea_2-5_l_hip_1_prt-binary.stl"
                      scale="0.001 0.001 0.001"/>
            </geometry>
            <material name="dblue">
                <color rgba="0 0 0.8 1"/>
            </material>
        </visual>
        <collision>
            <origin xyz="0.0428515000001 -0.026 0.151913"
                    rpy="1.57079632679 0 1.57079632679"/>
            <geometry>
                <mesh filename="package://iCub/meshes/simmechanics/sim_sea_2-5_l_hip_1_prt-binary.stl"
                      scale="0.001 0.001 0.001"/>
            </geometry>
        </collision>
    </link>
    <joint name="l_hip_pitch" type="revolute">
        <origin xyz="0.0064515 -0.026 -0.119913" rpy="0 0 -3.14159265359"/>
        <axis xyz="-2.22044604925e-16 -1.0 0.0"/>
        <parent link="root_link"/>
        <child link="l_hip_1"/>
        <limit effort="55.5" lower="-0.785398163397" upper="2.33874119767"
               velocity="5.1"/>
        <dynamics damping="1.0" friction="0.0"/>
    </joint>
    <link name="l_hip_2">
        <inertial>
            <origin xyz="-0.0011063 1.73e-05 -0.044574"
                    rpy="1.57079632679 0 1.57079632679"/>
            <mass value="0.415987"/>
            <inertia ixx="0.000475741" ixy="2.89355e-07" ixz="-6.72876e-08"
                     iyy="0.000279828" iyz="6.7417e-06" izz="0.000307828"/>
        </inertial>
        <visual>
            <origin xyz="0.0428514998093 -0.0701 0.151913"
                    rpy="1.57079632679 0 1.57079632679"/>
            <geometry>
                <mesh filename="package://iCub/meshes/simmechanics/sim_sea_2-5_l_hip_2_prt-binary.stl"
                      scale="0.001 0.001 0.001"/>
            </geometry>
            <material name="dgreen">
                <color rgba="0.1 0.8 0.1 1"/>
            </material>
        </visual>
        <collision>
            <origin xyz="0.0428514998093 -0.0701 0.151913"
                    rpy="1.57079632679 0 1.57079632679"/>
            <geometry>
                <mesh filename="package://iCub/meshes/simmechanics/sim_sea_2-5_l_hip_2_prt-binary.stl"
                      scale="0.001 0.001 0.001"/>
            </geometry>
        </collision>
    </link>
    <joint name="l_hip_roll" type="revolute">
        <origin xyz="0 0.0441 0" rpy="0 0 0"/>
        <axis xyz="1.0 0.0 2.22044604925e-16"/>
        <parent link="l_hip_1"/>
        <child link="l_hip_2"/>
        <limit effort="37.0" lower="-0.349065850399" upper="2.09439510239"
               velocity="7.64"/>
        <dynamics damping="1.0" friction="0.0"/>
    </joint>
    <link name="l_hip_3">
        <inertial>
            <origin xyz="-0.0001229 -0.0002823 0.008718"
                    rpy="-1.57079632679 0 -1.57079632679"/>
            <mass value="0.126212"/>
            <inertia ixx="0.01" ixy="2.67901e-07" ixz="-4.41463e-09" iyy="0.01"
                     iyz="3.32338e-08" izz="0.01"/>
        </inertial>
        <visual>
            <origin xyz="0.0437090614 0.0701000246 -0.226213"
                    rpy="-1.57079632679 0 -1.57079632679"/>
            <geometry>
                <mesh filename="package://iCub/meshes/simmechanics/sim_sea_2-5_l_upper_thigh_prt-binary.stl"
                      scale="0.001 0.001 0.001"/>
            </geometry>
            <material name="gray">
                <color rgba="0.5 0.5 0.5 1"/>
            </material>
        </visual>
        <collision>
            <origin xyz="0.0437090614 0.0701000246 -0.226213"
                    rpy="-1.57079632679 0 -1.57079632679"/>
            <geometry>
                <mesh filename="package://iCub/meshes/simmechanics/sim_sea_2-5_l_upper_thigh_prt-binary.stl"
                      scale="0.001 0.001 0.001"/>
            </geometry>
        </collision>
    </link>
    <joint name="l_leg_ft_sensor" type="fixed">
        <origin xyz="-0.0008302 7.52e-05 -0.0743" rpy="3.14159265359 0 0"/>
        <parent link="l_hip_2"/>
        <child link="l_hip_3"/>
        <dynamics damping="0.1"/>
    </joint>
    <link name="l_upper_leg">
        <inertial>
            <origin xyz="0.0033869 0.0001018 -0.078916"
                    rpy="1.57079632679 0 1.57079632679"/>
            <mass value="1.8084"/>
            <inertia ixx="0.00648512673084" ixy="-0.00012421121424"
                     ixz="-3.97399421479e-06" iyy="0.00146250529833"
                     iyz="-0.00013681806888" izz="0.00647619242046"/>
        </inertial>
        <visual>
            <origin xyz="0.0437090614 -0.0701000246 0.240813"
                    rpy="1.57079632679 0 1.57079632679"/>
            <geometry>
                <mesh filename="package://iCub/meshes/simmechanics/sim_sea_2-5_l_thigh_prt-binary.stl"
                      scale="0.001 0.001 0.001"/>
            </geometry>
            <material name="green">
                <color rgba="0 1 0 1"/>
            </material>
        </visual>
        <collision>
            <origin xyz="0.0437090614 -0.0701000246 0.240813"
                    rpy="1.57079632679 0 1.57079632679"/>
            <geometry>
                <mesh filename="package://iCub/meshes/simmechanics/sim_sea_2-5_l_thigh_prt-binary.stl"
                      scale="0.001 0.001 0.001"/>
            </geometry>
        </collision>
    </link>
    <joint name="l_hip_yaw" type="revolute">
        <origin xyz="0 0 0.0144" rpy="-3.14159265359 0 0"/>
        <axis xyz="0.0 2.22044604925e-16 1.0"/>
        <parent link="l_hip_3"/>
        <child link="l_upper_leg"/>
        <limit effort="37.0" lower="-1.3962634016" upper="1.3962634016" velocity="7.64"/>
        <dynamics damping="1.0" friction="0.0"/>
    </joint>
    <link name="l_upper_leg_back_contact"/>
    <joint name="l_upper_leg_back_contact_fixed_joint" type="fixed">
        <origin xyz="-0.0512567 0 0.0146" rpy="0 1.57079632679 0"/>
        <parent link="l_upper_leg"/>
        <child link="l_upper_leg_back_contact"/>
        <dynamics damping="0.1"/>
    </joint>
    <link name="l_upper_leg_dh_frame"/>
    <joint name="l_upper_leg_dh_frame_fixed_joint" type="fixed">
        <origin xyz="0 0 -0.145825" rpy="1.57079632679 0 0"/>
        <parent link="l_upper_leg"/>
        <child link="l_upper_leg_dh_frame"/>
        <dynamics damping="0.1"/>
    </joint>
    <link name="l_lower_leg">
        <inertial>
            <origin xyz="0.0009998 0.0034969 -0.088567"
                    rpy="1.57079632679 0 1.57079632679"/>
            <mass value="1.4724"/>
            <inertia ixx="0.00423698606499" ixy="-0.000239615181423"
                     ixz="6.76166218238e-05" iyy="0.00152221313636"
                     iyz="-0.00023314283575" izz="0.00457007183207"/>
        </inertial>
        <visual>
            <origin xyz="0.0437090614 -0.0701000248 0.386638"
                    rpy="1.57079632679 0 1.57079632679"/>
            <geometry>
                <mesh filename="package://iCub/meshes/simmechanics/sim_sea_2-5_l_shank_prt-binary.stl"
                      scale="0.001 0.001 0.001"/>
            </geometry>
            <material name="black">
                <color rgba="0 0 0 1"/>
            </material>
        </visual>
        <collision>
            <origin xyz="0.0437090614 -0.0701000248 0.386638"
                    rpy="1.57079632679 0 1.57079632679"/>
            <geometry>
                <mesh filename="package://iCub/meshes/simmechanics/sim_sea_2-5_l_shank_prt-binary.stl"
                      scale="0.001 0.001 0.001"/>
            </geometry>
        </collision>
    </link>
    <joint name="l_knee" type="revolute">
        <origin xyz="0 0 -0.145825" rpy="0 0 0"/>
        <axis xyz="-2.22044604925e-16 -1.0 0.0"/>
        <parent link="l_upper_leg"/>
        <child link="l_lower_leg"/>
        <limit effort="37.0" lower="-2.16420827247" upper="0.0698131700798"
               velocity="7.64"/>
        <dynamics damping="1.0" friction="0.0"/>
    </joint>
    <link name="l_ankle_1">
        <inertial>
            <origin xyz="0.0151531 0.000902 4.2e-05" rpy="1.57079632679 0 1.57079632679"/>
            <mass value="0.6798"/>
            <inertia ixx="0.000404474297345" ixy="-1.13226038781e-06"
                     ixz="3.04665105776e-05" iyy="0.00044788735407"
                     iyz="2.57265834141e-06" izz="0.000307603045377"/>
        </inertial>
        <visual>
            <origin xyz="0.0437090614 -0.0701000248 0.587138"
                    rpy="1.57079632679 0 1.57079632679"/>
            <geometry>
                <mesh filename="package://iCub/meshes/simmechanics/sim_sea_2-5_l_ankle_prt-binary.stl"
                      scale="0.001 0.001 0.001"/>
            </geometry>
            <material name="red">
                <color rgba="1 0 0 1"/>
            </material>
        </visual>
        <collision>
            <origin xyz="0.0437090614 -0.0701000248 0.587138"
                    rpy="1.57079632679 0 1.57079632679"/>
            <geometry>
                <mesh filename="package://iCub/meshes/simmechanics/sim_sea_2-5_l_ankle_prt-binary.stl"
                      scale="0.001 0.001 0.001"/>
            </geometry>
        </collision>
    </link>
    <joint name="l_ankle_pitch" type="revolute">
        <origin xyz="0 0 -0.2005" rpy="0 0 0"/>
        <axis xyz="2.22044604925e-16 1.0 0.0"/>
        <parent link="l_lower_leg"/>
        <child link="l_ankle_1"/>
        <limit effort="37.0" lower="-0.610865238198" upper="0.610865238198"
               velocity="7.64"/>
        <dynamics damping="1.0" friction="0.0"/>
    </joint>
    <link name="l_ankle_2">
        <inertial>
            <origin xyz="0.0011447 3.59999999998e-06 -0.03852"
                    rpy="1.57079632679 0 1.57079632679"/>
            <mass value="0.265122"/>
            <inertia ixx="0.01" ixy="-4.74606e-08" ixz="4.94571e-08" iyy="0.01"
                     iyz="-4.29975e-06" izz="0.01"/>
        </inertial>
        <visual>
            <origin xyz="0.0436816996186 -0.0701752001908 0.587138"
                    rpy="1.57079632679 0 1.57079632679"/>
            <geometry>
                <mesh filename="package://iCub/meshes/simmechanics/sim_sea_2-5_l_foot_prt-binary.stl"
                      scale="0.001 0.001 0.001"/>
            </geometry>
            <material name="blue">
                <color rgba="0 0 1 1"/>
            </material>
        </visual>
        <collision>
            <origin xyz="0.0436816996186 -0.0701752001908 0.587138"
                    rpy="1.57079632679 0 1.57079632679"/>
            <geometry>
                <mesh filename="package://iCub/meshes/simmechanics/sim_sea_2-5_l_foot_prt-binary.stl"
                      scale="0.001 0.001 0.001"/>
            </geometry>
        </collision>
    </link>
    <joint name="l_ankle_roll" type="revolute">
        <origin xyz="0 0 0" rpy="0 0 0"/>
        <axis xyz="1.0 0.0 2.22044604925e-16"/>
        <parent link="l_ankle_1"/>
        <child link="l_ankle_2"/>
        <limit effort="37.0" lower="-0.436332312999" upper="0.436332312999"
               velocity="7.64"/>
        <dynamics damping="1.0" friction="0.0"/>
    </joint>
    <link name="l_foot">
        <inertial>
            <origin xyz="0.0336669 -0.0053735 -0.001164"
                    rpy="-1.57079632679 0 -1.57079632679"/>
            <mass value="0.382968"/>
            <inertia ixx="0.00121242" ixy="-3.69533e-07" ixz="5.79273e-05"
                     iyy="0.00141712" iyz="-7.64972e-06" izz="0.000273846"/>
        </inertial>
        <visual>
            <origin xyz="0.0472090612 0.0701000248 -0.647438000286"
                    rpy="-1.57079632679 0 -1.57079632679"/>
            <geometry>
                <mesh filename="package://iCub/meshes/simmechanics/sim_sea_2-5_l_sole_prt-binary.stl"
                      scale="0.001 0.001 0.001"/>
            </geometry>
            <material name="yellow">
                <color rgba="1 1 0 1"/>
            </material>
        </visual>
        <collision>
            <origin xyz="0.03 -0.005 0.014" rpy="0.0 0.0 0.0"/>
            <geometry>
                <box size="0.16 0.072 0.001"/>
            </geometry>
        </collision>
    </link>
    <joint name="l_foot_ft_sensor" type="fixed">
        <origin xyz="-0.0035 0 -0.0605" rpy="3.14159265359 0 0"/>
        <parent link="l_ankle_2"/>
        <child link="l_foot"/>
        <dynamics damping="0.1"/>
    </joint>
    <link name="l_sole"/>
    <joint name="l_sole_fixed_joint" type="fixed">
        <origin xyz="0.0035 0 0.004" rpy="-3.14159265359 0 0"/>
        <parent link="l_foot"/>
        <child link="l_sole"/>
        <dynamics damping="0.1"/>
    </joint>
    <link name="l_sole_skin_0"/>
    <joint name="l_sole_skin_0_fixed_joint" type="fixed">
        <origin xyz="0.0932088 0.032368 0.0075" rpy="0 0 0"/>
        <parent link="l_foot"/>
        <child link="l_sole_skin_0"/>
        <dynamics damping="0.1"/>
    </joint>
    <link name="l_sole_skin_1"/>
    <joint name="l_sole_skin_1_fixed_joint" type="fixed">
        <origin xyz="0.0788512 0.0194399 0.0075" rpy="0 0 0"/>
        <parent link="l_foot"/>
        <child link="l_sole_skin_1"/>
        <dynamics damping="0.1"/>
    </joint>
    <link name="l_sole_skin_2"/>
    <joint name="l_sole_skin_2_fixed_joint" type="fixed">
        <origin xyz="0.0604768 0.0254106 0.0075" rpy="0 0 0"/>
        <parent link="l_foot"/>
        <child link="l_sole_skin_2"/>
        <dynamics damping="0.1"/>
    </joint>
    <link name="l_sole_skin_3"/>
    <joint name="l_sole_skin_3_fixed_joint" type="fixed">
        <origin xyz="0.04611923 0.0124825 0.0075" rpy="0 0 0"/>
        <parent link="l_foot"/>
        <child link="l_sole_skin_3"/>
        <dynamics damping="0.1"/>
    </joint>
    <link name="l_sole_skin_4"/>
    <joint name="l_sole_skin_4_fixed_joint" type="fixed">
        <origin xyz="0.05013609 -0.0064148 0.0075" rpy="0 0 0"/>
        <parent link="l_foot"/>
        <child link="l_sole_skin_4"/>
        <dynamics damping="0.1"/>
    </joint>
    <link name="l_sole_skin_8"/>
    <joint name="l_sole_skin_8_fixed_joint" type="fixed">
        <origin xyz="0.0725274 -0.0312828 0.0075" rpy="0 0 0"/>
        <parent link="l_foot"/>
        <child link="l_sole_skin_8"/>
        <dynamics damping="0.1"/>
    </joint>
    <link name="l_sole_skin_9"/>
    <joint name="l_sole_skin_9_fixed_joint" type="fixed">
        <origin xyz="0.0909018 -0.0372538 0.0075" rpy="0 0 0"/>
        <parent link="l_foot"/>
        <child link="l_sole_skin_9"/>
        <dynamics damping="0.1"/>
    </joint>
    <link name="l_sole_skin_10"/>
    <joint name="l_sole_skin_10_fixed_joint" type="fixed">
        <origin xyz="0.1052593 -0.0243254 0.0075" rpy="0 0 0"/>
        <parent link="l_foot"/>
        <child link="l_sole_skin_10"/>
        <dynamics damping="0.1"/>
    </joint>
    <link name="l_sole_skin_11"/>
    <joint name="l_sole_skin_11_fixed_joint" type="fixed">
        <origin xyz="0.1012425 -0.0054281 0.0075" rpy="0 0 0"/>
        <parent link="l_foot"/>
        <child link="l_sole_skin_11"/>
        <dynamics damping="0.1"/>
    </joint>
    <link name="l_sole_skin_12"/>
    <joint name="l_sole_skin_12_fixed_joint" type="fixed">
        <origin xyz="0.0828681 0.0005426 0.0075" rpy="0 0 0"/>
        <parent link="l_foot"/>
        <child link="l_sole_skin_12"/>
        <dynamics damping="0.1"/>
    </joint>
    <link name="l_sole_skin_13"/>
    <joint name="l_sole_skin_13_fixed_joint" type="fixed">
        <origin xyz="0.0685105 -0.0123855 0.0075" rpy="0 0 0"/>
        <parent link="l_foot"/>
        <child link="l_sole_skin_13"/>
        <dynamics damping="0.1"/>
    </joint>
    <link name="l_sole_skin_14"/>
    <joint name="l_sole_skin_14_fixed_joint" type="fixed">
        <origin xyz="0.1156 0.0074995 0.0075" rpy="0 0 0"/>
        <parent link="l_foot"/>
        <child link="l_sole_skin_14"/>
        <dynamics damping="0.1"/>
    </joint>
    <link name="l_sole_skin_15"/>
    <joint name="l_sole_skin_15_fixed_joint" type="fixed">
        <origin xyz="0.1115832 0.0263973 0.0075" rpy="0 0 0"/>
        <parent link="l_foot"/>
        <child link="l_sole_skin_15"/>
        <dynamics damping="0.1"/>
    </joint>
    <link name="l_sole_skin_17"/>
    <joint name="l_sole_skin_17_fixed_joint" type="fixed">
        <origin xyz="-0.0377191 0.0045385 0.0075" rpy="0 0 0"/>
        <parent link="l_foot"/>
        <child link="l_sole_skin_17"/>
        <dynamics damping="0.1"/>
    </joint>
    <link name="l_sole_skin_18"/>
    <joint name="l_sole_skin_18_fixed_joint" type="fixed">
        <origin xyz="-0.0520767 -0.0083897 0.0075" rpy="0 0 0"/>
        <parent link="l_foot"/>
        <child link="l_sole_skin_18"/>
        <dynamics damping="0.1"/>
    </joint>
    <link name="l_sole_skin_19"/>
    <joint name="l_sole_skin_19_fixed_joint" type="fixed">
        <origin xyz="-0.0480598 -0.027287 0.0075" rpy="0 0 0"/>
        <parent link="l_foot"/>
        <child link="l_sole_skin_19"/>
        <dynamics damping="0.1"/>
    </joint>
    <link name="l_sole_skin_20"/>
    <joint name="l_sole_skin_20_fixed_joint" type="fixed">
        <origin xyz="-0.0296854 -0.0332578 0.0075" rpy="0 0 0"/>
        <parent link="l_foot"/>
        <child link="l_sole_skin_20"/>
        <dynamics damping="0.1"/>
    </joint>
    <link name="l_sole_skin_21"/>
    <joint name="l_sole_skin_21_fixed_joint" type="fixed">
        <origin xyz="0.0277448 0.0184533 0.0075" rpy="0 0 0"/>
        <parent link="l_foot"/>
        <child link="l_sole_skin_21"/>
        <dynamics damping="0.1"/>
    </joint>
    <link name="l_sole_skin_22"/>
    <joint name="l_sole_skin_22_fixed_joint" type="fixed">
        <origin xyz="0.0357785 -0.0193429 0.0075" rpy="0 0 0"/>
        <parent link="l_foot"/>
        <child link="l_sole_skin_22"/>
        <dynamics damping="0.1"/>
    </joint>
    <link name="l_sole_skin_24"/>
    <joint name="l_sole_skin_24_fixed_joint" type="fixed">
        <origin xyz="0.0030466 -0.0263003 0.0075" rpy="0 0 0"/>
        <parent link="l_foot"/>
        <child link="l_sole_skin_24"/>
        <dynamics damping="0.1"/>
    </joint>
    <link name="l_sole_skin_25"/>
    <joint name="l_sole_skin_25_fixed_joint" type="fixed">
        <origin xyz="0.0174041 -0.0133722 0.0075" rpy="0 0 0"/>
        <parent link="l_foot"/>
        <child link="l_sole_skin_25"/>
        <dynamics damping="0.1"/>
    </joint>
    <link name="l_sole_skin_26"/>
    <joint name="l_sole_skin_26_fixed_joint" type="fixed">
        <origin xyz="0.0133873 0.0055251 0.0075" rpy="0 0 0"/>
        <parent link="l_foot"/>
        <child link="l_sole_skin_26"/>
        <dynamics damping="0.1"/>
    </joint>
    <link name="l_sole_skin_27"/>
    <joint name="l_sole_skin_27_fixed_joint" type="fixed">
        <origin xyz="-0.0049871 0.0114959 0.0075" rpy="0 0 0"/>
        <parent link="l_foot"/>
        <child link="l_sole_skin_27"/>
        <dynamics damping="0.1"/>
    </joint>
    <link name="l_sole_skin_28"/>
    <joint name="l_sole_skin_28_fixed_joint" type="fixed">
        <origin xyz="-0.0193447 -0.0014323 0.0075" rpy="0 0 0"/>
        <parent link="l_foot"/>
        <child link="l_sole_skin_28"/>
        <dynamics damping="0.1"/>
    </joint>
    <link name="l_sole_skin_29"/>
    <joint name="l_sole_skin_29_fixed_joint" type="fixed">
        <origin xyz="-0.0153279 -0.0203296 0.0075" rpy="0 0 0"/>
        <parent link="l_foot"/>
        <child link="l_sole_skin_29"/>
        <dynamics damping="0.1"/>
    </joint>
    <link name="torso_1">
        <inertial>
            <origin xyz="0.0270921359 0.02914798 -0.0004398" rpy="0 0 0"/>
            <mass value="0.67144"/>
            <inertia ixx="0.00040911" ixy="-1.04522e-06" ixz="-1.02516e-06"
                     iyy="0.000384141" iyz="6.50708e-06" izz="0.000299445"/>
        </inertial>
        <visual>
            <origin xyz="0.0270462998093 0.032 0.0364" rpy="0 0 0"/>
            <geometry>
                <mesh filename="package://iCub/meshes/simmechanics/sim_sea_2-5_lap_belt_1_prt-binary.stl"
                      scale="0.001 0.001 0.001"/>
            </geometry>
            <material name="pink">
                <color rgba="1 0 1 1"/>
            </material>
        </visual>
        <collision>
            <origin xyz="0.0270462998093 0.032 0.0364" rpy="0 0 0"/>
            <geometry>
                <mesh filename="package://iCub/meshes/simmechanics/sim_sea_2-5_lap_belt_1_prt-binary.stl"
                      scale="0.001 0.001 0.001"/>
            </geometry>
        </collision>
    </link>
    <joint name="torso_pitch" type="revolute">
        <origin xyz="0 0.0270463 0" rpy="1.57079632679 0 -1.57079632679"/>
        <axis xyz="1.0 0.0 0.0"/>
        <parent link="root_link"/>
        <child link="torso_1"/>
        <limit effort="50000" lower="-0.349065850399" upper="1.2217304764"
               velocity="50000"/>
        <dynamics damping="1.0" friction="0.0"/>
    </joint>
    <link name="torso_2">
        <inertial>
            <origin xyz="-0.000113507809265 0.0361525 0.0570963" rpy="0 0 0"/>
            <mass value="0.425685"/>
            <inertia ixx="0.000829234" ixy="2.37006e-08" ixz="9.25231e-08"
                     iyy="0.000436517" iyz="-1.74814e-07" izz="0.000604802"/>
        </inertial>
        <visual>
            <origin xyz="0 0.1433 0.0386531" rpy="0 0 0"/>
            <geometry>
                <mesh filename="package://iCub/meshes/simmechanics/sim_sea_2-5_lap_belt_2_prt-binary.stl"
                      scale="0.001 0.001 0.001"/>
            </geometry>
            <material name="cyan">
                <color rgba="0 1 1 1"/>
            </material>
        </visual>
        <collision>
            <origin xyz="0 0.1433 0.0386531" rpy="0 0 0"/>
            <geometry>
                <mesh filename="package://iCub/meshes/simmechanics/sim_sea_2-5_lap_belt_2_prt-binary.stl"
                      scale="0.001 0.001 0.001"/>
            </geometry>
        </collision>
    </link>
    <joint name="torso_roll" type="revolute">
        <origin xyz="0.0270462998093 0.032 -0.0573446" rpy="0 0 0"/>
        <axis xyz="0.0 0.0 -1.0"/>
        <parent link="torso_1"/>
        <child link="torso_2"/>
        <limit effort="50000" lower="-0.523598775598" upper="0.523598775598"
               velocity="50000"/>
        <dynamics damping="1.0" friction="0.0"/>
    </joint>
    <link name="chest">
        <inertial>
            <origin xyz="0.000188619190735 0.073091 -0.0472381" rpy="0 0 0"/>
            <mass value="7.638"/>
            <inertia ixx="0.0430324878618" ixy="2.91075388804e-05" ixz="0.000181985229949"
                     iyy="0.0440835725548" iyz="-0.000429106409108"
                     izz="0.0260563249911"/>
        </inertial>
        <visual>
            <origin xyz="0 0.0928 -0.024189" rpy="0 0 0"/>
            <geometry>
                <mesh filename="package://iCub/meshes/simmechanics/sim_sea_2-5_chest_bb_prt-binary.stl"
                      scale="0.001 0.001 0.001"/>
            </geometry>
            <material name="green">
                <color rgba="0 1 0 1"/>
            </material>
        </visual>
        <collision>
            <origin xyz="0 0.0928 -0.024189" rpy="0 0 0"/>
            <geometry>
                <mesh filename="package://iCub/meshes/simmechanics/sim_sea_2-5_chest_bb_prt-binary.stl"
                      scale="0.001 0.001 0.001"/>
            </geometry>
        </collision>
    </link>
    <joint name="torso_yaw" type="revolute">
        <origin xyz="0 0.05 0.0628421" rpy="0 0 0"/>
        <axis xyz="0.0 -1.0 0.0"/>
        <parent link="torso_2"/>
        <child link="chest"/>
        <limit effort="50000" lower="-0.872664625997" upper="0.872664625997"
               velocity="50000"/>
        <dynamics damping="1.0" friction="0.0"/>
    </joint>
    <link name="r_shoulder_1">
        <inertial>
            <origin xyz="-0.0122656014133 3.2e-05 -0.00321064290449" rpy="0 0 0"/>
            <mass value="0.114862"/>
            <inertia ixx="0.01" ixy="-1.65173e-08" ixz="-3.55626e-06" iyy="0.01"
                     iyz="-6.13337e-08" izz="0.01"/>
        </inertial>
        <visual>
            <origin xyz="0.0990079253076 0 -0.0265292487558" rpy="0 0 0"/>
            <geometry>
                <mesh filename="package://iCub/meshes/simmechanics/sim_sea_2-5_r_shoulder_1_prt-binary.stl"
                      scale="0.001 0.001 0.001"/>
            </geometry>
            <material name="white">
                <color rgba="1 1 1 1"/>
            </material>
        </visual>
        <collision>
            <origin xyz="0.0990079253076 0 -0.0265292487558" rpy="0 0 0"/>
            <geometry>
                <mesh filename="package://iCub/meshes/simmechanics/sim_sea_2-5_r_shoulder_1_prt-binary.stl"
                      scale="0.001 0.001 0.001"/>
            </geometry>
        </collision>
    </link>
    <joint name="r_shoulder_pitch" type="revolute">
        <origin xyz="-0.120015999809 0.0928 0.0079693"
                rpy="0 -0.523598883792 3.14159265359"/>
        <axis xyz="-0.965925926173 0.0 0.258819275525"/>
        <parent link="chest"/>
        <child link="r_shoulder_1"/>
        <limit effort="50000" lower="-1.66678943565" upper="0.174532925199"
               velocity="50000"/>
        <dynamics damping="1.0" friction="0.0"/>
    </joint>
    <link name="r_shoulder_2">
        <inertial>
            <origin xyz="-0.0214141709438 0.000271725272551 -0.0194402344535"
                    rpy="0 0 0"/>
            <mass value="0.238162"/>
            <inertia ixx="0.01" ixy="-1.12091e-07" ixz="1.02574e-05" iyy="0.01"
                     iyz="1.19785e-06" izz="0.01"/>
        </inertial>
        <visual>
            <origin xyz="0.106587808568 2.31914715418e-07 -0.0407392121175" rpy="0 0 0"/>
            <geometry>
                <mesh filename="package://iCub/meshes/simmechanics/sim_sea_2-5_r_shoulder_2_prt-binary.stl"
                      scale="0.001 0.001 0.001"/>
            </geometry>
            <material name="dblue">
                <color rgba="0 0 0.8 1"/>
            </material>
        </visual>
        <collision>
            <origin xyz="0.106587808568 2.31914715418e-07 -0.0407392121175" rpy="0 0 0"/>
            <geometry>
                <mesh filename="package://iCub/meshes/simmechanics/sim_sea_2-5_r_shoulder_2_prt-binary.stl"
                      scale="0.001 0.001 0.001"/>
            </geometry>
        </collision>
    </link>
    <joint name="r_shoulder_roll" type="revolute">
        <origin xyz="-0.00758046573227 0 0.0142102463639"
                rpy="-0.270597611583 -0.252680154648 -1.50155680035"/>
        <axis xyz="-0.258819 -2.77555756156e-17 -0.965926"/>
        <parent link="r_shoulder_1"/>
        <child link="r_shoulder_2"/>
        <limit effort="50000" lower="0.0" upper="2.80648943721" velocity="50000"/>
        <dynamics damping="1.0" friction="0.0"/>
    </joint>
    <link name="r_shoulder_3">
        <inertial>
            <origin xyz="-0.0267620766871 -6.99999999998e-06 0.0146999207713"
                    rpy="0 0 0"/>
            <mass value="0.35913"/>
            <inertia ixx="0.01" ixy="3.60361e-07" ixz="4.94445e-05" iyy="0.01"
                     iyz="2.65919e-07" izz="0.01"/>
        </inertial>
        <visual>
            <origin xyz="0.131933879164 0 -0.0353515667647" rpy="0 0 0"/>
            <geometry>
                <mesh filename="package://iCub/meshes/simmechanics/sim_sea_2-5_r_upper_arm_prt-binary.stl"
                      scale="0.001 0.001 0.001"/>
            </geometry>
            <material name="dgreen">
                <color rgba="0.1 0.8 0.1 1"/>
            </material>
        </visual>
        <collision>
            <origin xyz="0.131933879164 0 -0.0353515667647" rpy="0 0 0"/>
            <geometry>
                <mesh filename="package://iCub/meshes/simmechanics/sim_sea_2-5_r_upper_arm_prt-binary.stl"
                      scale="0.001 0.001 0.001"/>
            </geometry>
        </collision>
    </link>
    <joint name="r_shoulder_yaw" type="revolute">
        <origin xyz="-0.0253460713232 2.32750427306e-07 -0.00538764806457"
                rpy="-0.252689546175 0.0085186183214 0.067039889142"/>
        <axis xyz="0.965925843882 -2.22044604925e-16 -0.258818979447"/>
        <parent link="r_shoulder_2"/>
        <child link="r_shoulder_3"/>
        <limit effort="50000" lower="-0.645771823238" upper="1.3962634016"
               velocity="50000"/>
        <dynamics damping="1.0" friction="0.0"/>
    </joint>
    <link name="r_upper_arm">
        <inertial>
            <origin xyz="-0.006087 0.000126 0.0293121" rpy="0 1.30899700697 0"/>
            <mass value="0.745104"/>
            <inertia ixx="0.000509527" ixy="1.19292e-06" ixz="-1.17426e-05"
                     iyy="0.000668487" iyz="1.13363e-06" izz="0.000599254"/>
        </inertial>
        <visual>
            <origin xyz="-0.015 0 -0.1933" rpy="0 1.30899700697 0"/>
            <geometry>
                <mesh filename="package://iCub/meshes/simmechanics/sim_sea_2-5_r_elbow_prt-binary.stl"
                      scale="0.001 0.001 0.001"/>
            </geometry>
            <material name="gray">
                <color rgba="0.5 0.5 0.5 1"/>
            </material>
        </visual>
        <collision>
            <origin xyz="-0.015 0 -0.1933" rpy="0 1.30899700697 0"/>
            <geometry>
                <mesh filename="package://iCub/meshes/simmechanics/sim_sea_2-5_r_elbow_prt-binary.stl"
                      scale="0.001 0.001 0.001"/>
            </geometry>
        </collision>
    </link>
    <joint name="r_arm_ft_sensor" type="fixed">
        <origin xyz="-0.0508973017665 0 0.0291670296206" rpy="0 -1.30899700697 0"/>
        <parent link="r_shoulder_3"/>
        <child link="r_upper_arm"/>
        <dynamics damping="0.1"/>
    </joint>
    <link name="r_elbow_1">
        <inertial>
            <origin xyz="-0.00673912932843 0.0188019 -0.00465769236154" rpy="0 0 0"/>
            <mass value="0.267903"/>
            <inertia ixx="0.01" ixy="7.36974e-06" ixz="-1.04536e-05" iyy="0.01"
                     iyz="3.92498e-06" izz="0.01"/>
        </inertial>
        <visual>
            <origin xyz="0.259390463317 0.0224999 -0.0850325886962" rpy="0 0 0"/>
            <geometry>
                <mesh filename="package://iCub/meshes/simmechanics/sim_sea_2-5_r_elbow_prosup_prt-binary.stl"
                      scale="0.001 0.001 0.001"/>
            </geometry>
            <material name="green">
                <color rgba="0 1 0 1"/>
            </material>
        </visual>
        <collision>
            <origin xyz="0.259390463317 0.0224999 -0.0850325886962" rpy="0 0 0"/>
            <geometry>
                <mesh filename="package://iCub/meshes/simmechanics/sim_sea_2-5_r_elbow_prosup_prt-binary.stl"
                      scale="0.001 0.001 0.001"/>
            </geometry>
        </collision>
    </link>
    <joint name="r_elbow" type="revolute">
        <origin xyz="0 -0.0224999 0.07926" rpy="0 1.30899700697 0"/>
        <axis xyz="2.22044604925e-16 1.0 0.0"/>
        <parent link="r_upper_arm"/>
        <child link="r_elbow_1"/>
        <limit effort="50000" lower="0.261799387799" upper="1.85004900711"
               velocity="50000"/>
        <dynamics damping="1.0" friction="0.0"/>
    </joint>
    <link name="r_forearm">
        <inertial>
            <origin xyz="-0.0404391133886 -0.000328 0.00532733448387" rpy="0 0 0"/>
            <mass value="0.6347"/>
            <inertia ixx="0.000370044" ixy="-1.65419e-06" ixz="0.00010538"
                     iyy="0.000672279" iyz="1.1456e-06" izz="0.000553637"/>
        </inertial>
        <visual>
            <origin xyz="0.296886967375 0 -0.0795506015227" rpy="0 0 0"/>
            <geometry>
                <mesh filename="package://iCub/meshes/simmechanics/sim_sea_2-5_r_forearm_prt-binary.stl"
                      scale="0.001 0.001 0.001"/>
            </geometry>
            <material name="black">
                <color rgba="0 0 0 1"/>
            </material>
        </visual>
        <collision>
            <origin xyz="0.296886967375 0 -0.0795506015227" rpy="0 0 0"/>
            <geometry>
                <mesh filename="package://iCub/meshes/simmechanics/sim_sea_2-5_r_forearm_prt-binary.stl"
                      scale="0.001 0.001 0.001"/>
            </geometry>
        </collision>
    </link>
    <joint name="r_wrist_prosup" type="revolute">
        <origin xyz="-0.0384624299027 0.0224999 -0.00522316819403" rpy="0 0 0"/>
        <axis xyz="0.965925843882 -2.22044604925e-16 -0.258818979447"/>
        <parent link="r_elbow_1"/>
        <child link="r_forearm"/>
        <limit effort="50000" lower="-1.0471975512" upper="1.0471975512"
               velocity="50000"/>
        <dynamics damping="1.0" friction="0.0"/>
    </joint>
    <link name="r_forearm_skin_0"/>
    <joint name="r_forearm_skin_0_fixed_joint" type="fixed">
        <origin xyz="-0.0454493286618 0.030077 -0.00628656037901"
                rpy="1.69181522292 -0.271026744341 -3.06880438227"/>
        <parent link="r_forearm"/>
        <child link="r_forearm_skin_0"/>
        <dynamics damping="0.1"/>
    </joint>
    <link name="r_forearm_skin_1"/>
    <joint name="r_forearm_skin_1_fixed_joint" type="fixed">
        <origin xyz="-0.0333728935826 0.028826 -0.0198456867711"
                rpy="1.86694023278 -0.274442533764 -3.09946977984"/>
        <parent link="r_forearm"/>
        <child link="r_forearm_skin_1"/>
        <dynamics damping="0.1"/>
    </joint>
    <link name="r_forearm_skin_2"/>
    <joint name="r_forearm_skin_2_fixed_joint" type="fixed">
        <origin xyz="-0.0146988929852 0.031279 -0.0160117338371"
                rpy="1.72847287019 -0.264015219116 -3.12733260687"/>
        <parent link="r_forearm"/>
        <child link="r_forearm_skin_2"/>
        <dynamics damping="0.1"/>
    </joint>
    <link name="r_forearm_skin_3"/>
    <joint name="r_forearm_skin_3_fixed_joint" type="fixed">
        <origin xyz="-0.045567293622 -0.030891 -0.00633000929351"
                rpy="-1.69487280859 -0.269757727104 3.07959743574"/>
        <parent link="r_forearm"/>
        <child link="r_forearm_skin_3"/>
        <dynamics damping="0.1"/>
    </joint>
    <link name="r_forearm_skin_4"/>
    <joint name="r_forearm_skin_4_fixed_joint" type="fixed">
        <origin xyz="-0.0635326332996 -0.0281163 -0.00899784258066"
                rpy="-1.80734960194 -0.0393131796327 2.97997643632"/>
        <parent link="r_forearm"/>
        <child link="r_forearm_skin_4"/>
        <dynamics damping="0.1"/>
    </joint>
    <link name="r_forearm_skin_5"/>
    <joint name="r_forearm_skin_5_fixed_joint" type="fixed">
        <origin xyz="-0.0688211941968 -0.0179483 -0.0231133361791"
                rpy="-2.5410475806 -0.385627260642 3.05486989667"/>
        <parent link="r_forearm"/>
        <child link="r_forearm_skin_5"/>
        <dynamics damping="0.1"/>
    </joint>
    <link name="r_forearm_skin_6"/>
    <joint name="r_forearm_skin_6_fixed_joint" type="fixed">
        <origin xyz="-0.0333948436255 -0.0295479 -0.0198325583433"
                rpy="-1.86628164653 -0.272886336181 3.10448585021"/>
        <parent link="r_forearm"/>
        <child link="r_forearm_skin_6"/>
        <dynamics damping="0.1"/>
    </joint>
    <link name="r_forearm_skin_7"/>
    <joint name="r_forearm_skin_7_fixed_joint" type="fixed">
        <origin xyz="-0.0147224260074 -0.0319422 -0.0159326482703"
                rpy="-1.72564640857 -0.263992900722 3.12721254266"/>
        <parent link="r_forearm"/>
        <child link="r_forearm_skin_7"/>
        <dynamics damping="0.1"/>
    </joint>
    <link name="r_forearm_skin_8"/>
    <joint name="r_forearm_skin_8_fixed_joint" type="fixed">
        <origin xyz="-0.0228528628554 -0.0097862 -0.041885146375"
                rpy="-2.94801979137 -0.270605090512 3.13980557285"/>
        <parent link="r_forearm"/>
        <child link="r_forearm_skin_8"/>
        <dynamics damping="0.1"/>
    </joint>
    <link name="r_forearm_skin_9"/>
    <joint name="r_forearm_skin_9_fixed_joint" type="fixed">
        <origin xyz="-0.0376032734683 -0.018955 -0.0340163371186"
                rpy="-2.58406517708 -0.2933217196 3.12128407396"/>
        <parent link="r_forearm"/>
        <child link="r_forearm_skin_9"/>
        <dynamics damping="0.1"/>
    </joint>
    <link name="r_forearm_skin_10"/>
    <joint name="r_forearm_skin_10_fixed_joint" type="fixed">
        <origin xyz="-0.0542285210888 -0.0097861 -0.0321469082866"
                rpy="-2.94123313406 -0.328304471922 3.1276263754"/>
        <parent link="r_forearm"/>
        <child link="r_forearm_skin_10"/>
        <dynamics damping="0.1"/>
    </joint>
    <link name="r_forearm_skin_11"/>
    <joint name="r_forearm_skin_11_fixed_joint" type="fixed">
        <origin xyz="-0.0542240912024 0.009043 -0.0321431259452"
                rpy="2.93929835957 -0.329101389745 -3.12731916446"/>
        <parent link="r_forearm"/>
        <child link="r_forearm_skin_11"/>
        <dynamics damping="0.1"/>
    </joint>
    <link name="r_forearm_skin_12"/>
    <joint name="r_forearm_skin_12_fixed_joint" type="fixed">
        <origin xyz="-0.0375994633868 0.018216 -0.0340191179961"
                rpy="2.58303505964 -0.29483050207 -3.12026580314"/>
        <parent link="r_forearm"/>
        <child link="r_forearm_skin_12"/>
        <dynamics damping="0.1"/>
    </joint>
    <link name="r_forearm_skin_13"/>
    <joint name="r_forearm_skin_13_fixed_joint" type="fixed">
        <origin xyz="-0.0228550868405 0.009048 -0.0418919009209"
                rpy="2.94896679198 -0.270583947189 -3.13981880352"/>
        <parent link="r_forearm"/>
        <child link="r_forearm_skin_13"/>
        <dynamics damping="0.1"/>
    </joint>
    <link name="r_forearm_skin_14"/>
    <joint name="r_forearm_skin_14_fixed_joint" type="fixed">
        <origin xyz="-0.0687703276364 0.01716 -0.0230239558511"
                rpy="2.48044991868 -0.295542566281 -2.91877349139"/>
        <parent link="r_forearm"/>
        <child link="r_forearm_skin_14"/>
        <dynamics damping="0.1"/>
    </joint>
    <link name="r_forearm_skin_15"/>
    <joint name="r_forearm_skin_15_fixed_joint" type="fixed">
        <origin xyz="-0.0633786419662 0.027145 -0.00879405455544"
                rpy="1.80492769741 -0.289783281916 -3.02765891428"/>
        <parent link="r_forearm"/>
        <child link="r_forearm_skin_15"/>
        <dynamics damping="0.1"/>
    </joint>
    <link name="r_forearm_skin_16"/>
    <joint name="r_forearm_skin_16_fixed_joint" type="fixed">
        <origin xyz="-0.03792482187 0.030487 0.0206369503605"
                rpy="1.41280007026 -0.25082462139 -3.06572742343"/>
        <parent link="r_forearm"/>
        <child link="r_forearm_skin_16"/>
        <dynamics damping="0.1"/>
    </joint>
    <link name="r_forearm_skin_17"/>
    <joint name="r_forearm_skin_17_fixed_joint" type="fixed">
        <origin xyz="-0.0543170548821 0.027725 0.0303291240179"
                rpy="1.27223716205 -0.23059304703 -3.03195542837"/>
        <parent link="r_forearm"/>
        <child link="r_forearm_skin_17"/>
        <dynamics damping="0.1"/>
    </joint>
    <link name="r_forearm_skin_19"/>
    <joint name="r_forearm_skin_19_fixed_joint" type="fixed">
        <origin xyz="-0.0381266107138 -0.0312941 0.020690605393"
                rpy="-1.41560888703 -0.252569290226 3.07715217889"/>
        <parent link="r_forearm"/>
        <child link="r_forearm_skin_19"/>
        <dynamics damping="0.1"/>
    </joint>
    <link name="r_forearm_skin_22"/>
    <joint name="r_forearm_skin_22_fixed_joint" type="fixed">
        <origin xyz="-0.0544173950421 -0.0287223 0.0306037516609"
                rpy="-1.2658242728 -0.234328151379 3.04788317971"/>
        <parent link="r_forearm"/>
        <child link="r_forearm_skin_22"/>
        <dynamics damping="0.1"/>
    </joint>
    <link name="r_forearm_skin_24"/>
    <joint name="r_forearm_skin_24_fixed_joint" type="fixed">
        <origin xyz="-0.0700345319564 -0.0097164 0.050069108714"
                rpy="-0.23489327644 -0.0388172993982 3.08676345459"/>
        <parent link="r_forearm"/>
        <child link="r_forearm_skin_24"/>
        <dynamics damping="0.1"/>
    </joint>
    <link name="r_forearm_skin_25"/>
    <joint name="r_forearm_skin_25_fixed_joint" type="fixed">
        <origin xyz="-0.0535999216295 -0.0182238 0.0454698125045"
                rpy="-0.564295527715 -0.136980272197 3.05963182792"/>
        <parent link="r_forearm"/>
        <child link="r_forearm_skin_25"/>
        <dynamics damping="0.1"/>
    </joint>
    <link name="r_forearm_skin_28"/>
    <joint name="r_forearm_skin_28_fixed_joint" type="fixed">
        <origin xyz="-0.0535859272148 0.017412 0.045352037397"
                rpy="0.59077064408 -0.0531607226063 3.10597081167"/>
        <parent link="r_forearm"/>
        <child link="r_forearm_skin_28"/>
        <dynamics damping="0.1"/>
    </joint>
    <link name="r_forearm_skin_29"/>
    <joint name="r_forearm_skin_29_fixed_joint" type="fixed">
        <origin xyz="-0.0700355805031 0.008954 0.0500111036233"
                rpy="0.248630982209 -0.0383136556786 -3.08328999116"/>
        <parent link="r_forearm"/>
        <child link="r_forearm_skin_29"/>
        <dynamics damping="0.1"/>
    </joint>
    <link name="r_forearm_dh_frame"/>
    <joint name="r_forearm_dh_frame_fixed_joint" type="fixed">
        <origin xyz="-0.102871102373 7.00000000002e-06 0.0275642213111"
                rpy="-0.261799319827 0 -1.57079632679"/>
        <parent link="r_forearm"/>
        <child link="r_forearm_dh_frame"/>
        <dynamics damping="0.1"/>
    </joint>
    <link name="r_wrist_1">
        <inertial>
            <origin xyz="0.000986101955547 -0.001176 0.00410132736724" rpy="0 0 0"/>
            <mass value="0.0362615"/>
            <inertia ixx="0.01" ixy="-3.10462e-08" ixz="-9.44554e-07" iyy="0.01"
                     iyz="-1.59685e-07" izz="0.01"/>
        </inertial>
        <visual>
            <origin xyz="0.400392176248 -7.00000000009e-06 -0.104748304516" rpy="0 0 0"/>
            <geometry>
                <mesh filename="package://iCub/meshes/simmechanics/sim_sea_2-5_r_wrist_pitch_prt-binary.stl"
                      scale="0.001 0.001 0.001"/>
            </geometry>
            <material name="red">
                <color rgba="1 0 0 1"/>
            </material>
        </visual>
        <collision>
            <origin xyz="0.400392176248 -7.00000000009e-06 -0.104748304516" rpy="0 0 0"/>
            <geometry>
                <mesh filename="package://iCub/meshes/simmechanics/sim_sea_2-5_r_wrist_pitch_prt-binary.stl"
                      scale="0.001 0.001 0.001"/>
            </geometry>
        </collision>
    </link>
    <joint name="r_wrist_pitch" type="revolute">
        <origin xyz="-0.103505208873 7.00000000002e-06 0.0251977029936" rpy="0 0 0"/>
        <axis xyz="0.258818979447 0.0 0.965925843882"/>
        <parent link="r_forearm"/>
        <child link="r_wrist_1"/>
        <limit effort="50000" lower="-1.3962634016" upper="0.436332312999"
               velocity="50000"/>
        <dynamics damping="1.0" friction="0.0"/>
    </joint>
    <link name="r_hand">
        <inertial>
            <origin xyz="-0.064668163717 0.0056002 0.0226812940918" rpy="0 0 0"/>
            <mass value="0.248289"/>
            <inertia ixx="0.01" ixy="-2.3536e-06" ixz="3.61526e-05" iyy="0.01"
                     iyz="2.07146e-05" izz="0.01"/>
        </inertial>
        <visual>
            <origin xyz="0.399758069749 0.0194929 -0.107114822834" rpy="0 0 0"/>
            <geometry>
                <mesh filename="package://iCub/meshes/simmechanics/sim_sea_2-5_r_hand_prt-binary.stl"
                      scale="0.001 0.001 0.001"/>
            </geometry>
            <material name="blue">
                <color rgba="0 0 1 1"/>
            </material>
        </visual>
        <collision>
            <origin xyz="0.399758069749 0.0194929 -0.107114822834" rpy="0 0 0"/>
            <geometry>
                <mesh filename="package://iCub/meshes/simmechanics/sim_sea_2-5_r_hand_prt-binary.stl"
                      scale="0.001 0.001 0.001"/>
            </geometry>
        </collision>
    </link>
    <joint name="r_wrist_yaw" type="revolute">
        <origin xyz="0.000634106499644 -0.0194999 0.00236651831751" rpy="0 0 0"/>
        <axis xyz="2.22044604925e-16 1.0 0.0"/>
        <parent link="r_wrist_1"/>
        <child link="r_hand"/>
        <limit effort="50000" lower="-0.349065850399" upper="0.436332312999"
               velocity="50000"/>
        <dynamics damping="1.0" friction="0.0"/>
    </joint>
    <link name="r_hand_dh_frame"/>
    <joint name="r_hand_dh_frame_fixed_joint" type="fixed">
        <origin xyz="-0.0576542978428 -0.0055568 0.0136938323083"
                rpy="-1.57079632679 -0.261799319827 3.14159265359"/>
        <parent link="r_hand"/>
        <child link="r_hand_dh_frame"/>
        <dynamics damping="0.1"/>
    </joint>
    <link name="l_shoulder_1">
        <inertial>
            <origin xyz="-0.008985 -3.3e-05 -0.0088998" rpy="0 0 0"/>
            <mass value="0.114882"/>
            <inertia ixx="0.01" ixy="-1.77064e-08" ixz="3.55951e-06" iyy="0.01"
                     iyz="6.57597e-08" izz="0.01"/>
        </inertial>
        <visual>
            <origin xyz="-0.120257482 0 -0.032223" rpy="0 0 0"/>
            <geometry>
                <mesh filename="package://iCub/meshes/simmechanics/sim_sea_2-5_l_shoulder_1_prt-binary.stl"
                      scale="0.001 0.001 0.001"/>
            </geometry>
            <material name="yellow">
                <color rgba="1 1 0 1"/>
            </material>
        </visual>
        <collision>
            <origin xyz="-0.120257482 0 -0.032223" rpy="0 0 0"/>
            <geometry>
                <mesh filename="package://iCub/meshes/simmechanics/sim_sea_2-5_l_shoulder_1_prt-binary.stl"
                      scale="0.001 0.001 0.001"/>
            </geometry>
        </collision>
    </link>
    <joint name="l_shoulder_pitch" type="revolute">
        <origin xyz="0.120016000191 0.0928 0.0079693" rpy="0 0 0"/>
        <axis xyz="0.965926 0.0 0.258819"/>
        <parent link="chest"/>
        <child link="l_shoulder_1"/>
        <limit effort="50000" lower="-1.66678943565" upper="0.174532925199"
               velocity="50000"/>
        <dynamics damping="1.0" friction="0.0"/>
    </joint>
    <link name="l_shoulder_2">
        <inertial>
            <origin xyz="0.0214745951272 0.000268957899687 -0.0194107361535" rpy="0 0 0"/>
            <mass value="0.238162"/>
            <inertia ixx="0.01" ixy="1.19701e-07" ixz="-1.29687e-05" iyy="0.01"
                     iyz="1.20112e-06" izz="0.01"/>
        </inertial>
        <visual>
            <origin xyz="-0.106586691581 1.10800934344e-07 -0.040743380771" rpy="0 0 0"/>
            <geometry>
                <mesh filename="package://iCub/meshes/simmechanics/sim_sea_2-5_l_shoulder_2_prt-binary.stl"
                      scale="0.001 0.001 0.001"/>
            </geometry>
            <material name="pink">
                <color rgba="1 0 1 1"/>
            </material>
        </visual>
        <collision>
            <origin xyz="-0.106586691581 1.10800934344e-07 -0.040743380771" rpy="0 0 0"/>
            <geometry>
                <mesh filename="package://iCub/meshes/simmechanics/sim_sea_2-5_l_shoulder_2_prt-binary.stl"
                      scale="0.001 0.001 0.001"/>
            </geometry>
        </collision>
    </link>
    <joint name="l_shoulder_roll" type="revolute">
        <origin xyz="-0.013671 0 0.0085204"
                rpy="0.270597317916 0.252680177542 -1.50155688559"/>
        <axis xyz="-0.258819 2.77555756156e-17 0.965926"/>
        <parent link="l_shoulder_1"/>
        <child link="l_shoulder_2"/>
        <limit effort="50000" lower="0.0" upper="2.80648943721" velocity="50000"/>
        <dynamics damping="1.0" friction="0.0"/>
    </joint>
    <link name="l_shoulder_3">
        <inertial>
            <origin xyz="0.026798412222 -1.6e-05 0.0146956806177" rpy="0 0 0"/>
            <mass value="0.35913"/>
            <inertia ixx="0.01" ixy="-2.22441e-07" ixz="-4.95846e-05" iyy="0.01"
                     iyz="1.07538e-07" izz="0.01"/>
        </inertial>
        <visual>
            <origin xyz="-0.131901037685 0 -0.0353427669194" rpy="0 0 0"/>
            <geometry>
                <mesh filename="package://iCub/meshes/simmechanics/sim_sea_2-5_l_upper_arm_prt-binary.stl"
                      scale="0.001 0.001 0.001"/>
            </geometry>
            <material name="cyan">
                <color rgba="0 1 1 1"/>
            </material>
        </visual>
        <collision>
            <origin xyz="-0.131901037685 0 -0.0353427669194" rpy="0 0 0"/>
            <geometry>
                <mesh filename="package://iCub/meshes/simmechanics/sim_sea_2-5_l_upper_arm_prt-binary.stl"
                      scale="0.001 0.001 0.001"/>
            </geometry>
        </collision>
    </link>
    <joint name="l_shoulder_yaw" type="revolute">
        <origin xyz="0.0253143468312 1.11636438205e-07 -0.00540061656265"
                rpy="-0.252689546175 -0.0085186183214 -0.067039889142"/>
        <axis xyz="0.965925843882 2.22044604925e-16 0.258818979447"/>
        <parent link="l_shoulder_2"/>
        <child link="l_shoulder_3"/>
        <limit effort="50000" lower="-0.645771823238" upper="1.3962634016"
               velocity="50000"/>
        <dynamics damping="1.0" friction="0.0"/>
    </joint>
    <link name="l_upper_arm">
        <inertial>
            <origin xyz="-0.006121 -0.000189 0.0293684"
                    rpy="0 -1.30899700697 -3.14159265359"/>
            <mass value="0.746799"/>
            <inertia ixx="0.000509731" ixy="-6.90767e-07" ixz="1.20048e-05"
                     iyy="0.00067086" iyz="3.11833e-06" izz="0.000601202"/>
        </inertial>
        <visual>
            <origin xyz="-0.015 0 -0.1933" rpy="0 -1.30899700697 -3.14159265359"/>
            <geometry>
                <mesh filename="package://iCub/meshes/simmechanics/sim_sea_2-5_l_elbow_prt-binary.stl"
                      scale="0.001 0.001 0.001"/>
            </geometry>
            <material name="green">
                <color rgba="0 1 0 1"/>
            </material>
        </visual>
        <collision>
            <origin xyz="-0.015 0 -0.1933" rpy="0 -1.30899700697 -3.14159265359"/>
            <geometry>
                <mesh filename="package://iCub/meshes/simmechanics/sim_sea_2-5_l_elbow_prt-binary.stl"
                      scale="0.001 0.001 0.001"/>
            </geometry>
        </collision>
    </link>
    <joint name="l_arm_ft_sensor" type="fixed">
        <origin xyz="0.0509301432452 0 0.0291758294659"
                rpy="0 -1.30899700697 3.14159265359"/>
        <parent link="l_shoulder_3"/>
        <child link="l_upper_arm"/>
        <dynamics damping="0.1"/>
    </joint>
    <link name="l_elbow_1">
        <inertial>
            <origin xyz="0.00673912932843 0.0303019 -0.00465769236154" rpy="0 0 0"/>
            <mass value="0.267903"/>
            <inertia ixx="0.01" ixy="-7.37159e-06" ixz="1.04505e-05" iyy="0.01"
                     iyz="3.9319e-06" izz="0.01"/>
        </inertial>
        <visual>
            <origin xyz="-0.259390463317 0.0339999 -0.0850325886962" rpy="0 0 0"/>
            <geometry>
                <mesh filename="package://iCub/meshes/simmechanics/sim_sea_2-5_l_elbow_prosup_prt-binary.stl"
                      scale="0.001 0.001 0.001"/>
            </geometry>
            <material name="white">
                <color rgba="1 1 1 1"/>
            </material>
        </visual>
        <collision>
            <origin xyz="-0.259390463317 0.0339999 -0.0850325886962" rpy="0 0 0"/>
            <geometry>
                <mesh filename="package://iCub/meshes/simmechanics/sim_sea_2-5_l_elbow_prosup_prt-binary.stl"
                      scale="0.001 0.001 0.001"/>
            </geometry>
        </collision>
    </link>
    <joint name="l_elbow" type="revolute">
        <origin xyz="0 0.0339999 0.07926" rpy="0 -1.30899700697 -3.14159265359"/>
        <axis xyz="2.22044604925e-16 -1.0 0.0"/>
        <parent link="l_upper_arm"/>
        <child link="l_elbow_1"/>
        <limit effort="50000" lower="0.261799387799" upper="1.85004900711"
               velocity="50000"/>
        <dynamics damping="1.0" friction="0.0"/>
    </joint>
    <link name="l_forearm">
        <inertial>
            <origin xyz="0.0404511828823 -0.000686 0.00532363214379" rpy="0 0 0"/>
            <mass value="0.636185"/>
            <inertia ixx="0.000371447" ixy="4.34562e-06" ixz="-0.000105871"
                     iyy="0.000674229" iyz="4.05222e-06" izz="0.000557115"/>
        </inertial>
        <visual>
            <origin xyz="-0.296886967375 0 -0.0795506015227" rpy="0 0 0"/>
            <geometry>
                <mesh filename="package://iCub/meshes/simmechanics/sim_sea_2-5_l_forearm_prt-binary.stl"
                      scale="0.001 0.001 0.001"/>
            </geometry>
            <material name="dblue">
                <color rgba="0 0 0.8 1"/>
            </material>
        </visual>
        <collision>
            <origin xyz="-0.296886967375 0 -0.0795506015227" rpy="0 0 0"/>
            <geometry>
                <mesh filename="package://iCub/meshes/simmechanics/sim_sea_2-5_l_forearm_prt-binary.stl"
                      scale="0.001 0.001 0.001"/>
            </geometry>
        </collision>
    </link>
    <joint name="l_wrist_prosup" type="revolute">
        <origin xyz="0.0384624299027 0.0339999 -0.00522316819403" rpy="0 0 0"/>
        <axis xyz="0.965925843882 2.22044604925e-16 0.258818979447"/>
        <parent link="l_elbow_1"/>
        <child link="l_forearm"/>
        <limit effort="50000" lower="-1.0471975512" upper="1.0471975512"
               velocity="50000"/>
        <dynamics damping="1.0" friction="0.0"/>
    </joint>
    <link name="l_forearm_skin_0"/>
    <joint name="l_forearm_skin_0_fixed_joint" type="fixed">
        <origin xyz="0.0454493286618 -0.0323169 -0.00628656037901"
                rpy="1.69181522292 -0.271026744341 0.0727882713185"/>
        <parent link="l_forearm"/>
        <child link="l_forearm_skin_0"/>
        <dynamics damping="0.1"/>
    </joint>
    <link name="l_forearm_skin_1"/>
    <joint name="l_forearm_skin_1_fixed_joint" type="fixed">
        <origin xyz="0.0333728935826 -0.0310662 -0.0198456867711"
                rpy="1.86694023278 -0.274442533764 0.0421228737473"/>
        <parent link="l_forearm"/>
        <child link="l_forearm_skin_1"/>
        <dynamics damping="0.1"/>
    </joint>
    <link name="l_forearm_skin_2"/>
    <joint name="l_forearm_skin_2_fixed_joint" type="fixed">
        <origin xyz="0.0146988929852 -0.0335184 -0.0160117338371"
                rpy="1.72847287019 -0.264015219116 0.0142600467197"/>
        <parent link="l_forearm"/>
        <child link="l_forearm_skin_2"/>
        <dynamics damping="0.1"/>
    </joint>
    <link name="l_forearm_skin_3"/>
    <joint name="l_forearm_skin_3_fixed_joint" type="fixed">
        <origin xyz="0.045567293622 0.028651 -0.00633000929351"
                rpy="-1.69487280859 -0.269757727104 -0.061995217851"/>
        <parent link="l_forearm"/>
        <child link="l_forearm_skin_3"/>
        <dynamics damping="0.1"/>
    </joint>
    <link name="l_forearm_skin_4"/>
    <joint name="l_forearm_skin_4_fixed_joint" type="fixed">
        <origin xyz="0.0635326332996 0.025877 -0.00899784258066"
                rpy="-1.81747870108 -0.287406884885 -0.0998316152826"/>
        <parent link="l_forearm"/>
        <child link="l_forearm_skin_4"/>
        <dynamics damping="0.1"/>
    </joint>
    <link name="l_forearm_skin_5"/>
    <joint name="l_forearm_skin_5_fixed_joint" type="fixed">
        <origin xyz="0.0688211941968 0.015709 -0.0231133361791"
                rpy="-2.5410475806 -0.385627260642 -0.0867227569203"/>
        <parent link="l_forearm"/>
        <child link="l_forearm_skin_5"/>
        <dynamics damping="0.1"/>
    </joint>
    <link name="l_forearm_skin_6"/>
    <joint name="l_forearm_skin_6_fixed_joint" type="fixed">
        <origin xyz="0.0333948436255 0.027308 -0.0198325583433"
                rpy="-1.86628164653 -0.272886336181 -0.0371068033783"/>
        <parent link="l_forearm"/>
        <child link="l_forearm_skin_6"/>
        <dynamics damping="0.1"/>
    </joint>
    <link name="l_forearm_skin_7"/>
    <joint name="l_forearm_skin_7_fixed_joint" type="fixed">
        <origin xyz="0.0147224260074 0.029702 -0.0159326482703"
                rpy="-1.72564640857 -0.263992900722 -0.0143801109253"/>
        <parent link="l_forearm"/>
        <child link="l_forearm_skin_7"/>
        <dynamics damping="0.1"/>
    </joint>
    <link name="l_forearm_skin_8"/>
    <joint name="l_forearm_skin_8_fixed_joint" type="fixed">
        <origin xyz="0.0228528628554 0.007546 -0.041885146375"
                rpy="-2.94801979137 -0.270605090512 -0.00178708074348"/>
        <parent link="l_forearm"/>
        <child link="l_forearm_skin_8"/>
        <dynamics damping="0.1"/>
    </joint>
    <link name="l_forearm_skin_9"/>
    <joint name="l_forearm_skin_9_fixed_joint" type="fixed">
        <origin xyz="0.0376032734683 0.016715 -0.0340163371186"
                rpy="-2.58406517708 -0.2933217196 -0.0203085796276"/>
        <parent link="l_forearm"/>
        <child link="l_forearm_skin_9"/>
        <dynamics damping="0.1"/>
    </joint>
    <link name="l_forearm_skin_10"/>
    <joint name="l_forearm_skin_10_fixed_joint" type="fixed">
        <origin xyz="0.0542285210888 0.007546 -0.0321469082866"
                rpy="-2.94123313406 -0.328304471922 -0.0139662781936"/>
        <parent link="l_forearm"/>
        <child link="l_forearm_skin_10"/>
        <dynamics damping="0.1"/>
    </joint>
    <link name="l_forearm_skin_11"/>
    <joint name="l_forearm_skin_11_fixed_joint" type="fixed">
        <origin xyz="0.0542240912024 -0.0112832 -0.0321431259452"
                rpy="2.93929835957 -0.329101389745 0.0142734891292"/>
        <parent link="l_forearm"/>
        <child link="l_forearm_skin_11"/>
        <dynamics damping="0.1"/>
    </joint>
    <link name="l_forearm_skin_12"/>
    <joint name="l_forearm_skin_12_fixed_joint" type="fixed">
        <origin xyz="0.0375994633868 -0.0204556 -0.0340191179961"
                rpy="2.58303505964 -0.29483050207 0.021326850448"/>
        <parent link="l_forearm"/>
        <child link="l_forearm_skin_12"/>
        <dynamics damping="0.1"/>
    </joint>
    <link name="l_forearm_skin_13"/>
    <joint name="l_forearm_skin_13_fixed_joint" type="fixed">
        <origin xyz="0.0228550868405 -0.0112878 -0.0418919009209"
                rpy="2.94896679198 -0.270583947189 0.00177385006765"/>
        <parent link="l_forearm"/>
        <child link="l_forearm_skin_13"/>
        <dynamics damping="0.1"/>
    </joint>
    <link name="l_forearm_skin_14"/>
    <joint name="l_forearm_skin_14_fixed_joint" type="fixed">
        <origin xyz="0.0687703276364 -0.0193999 -0.0230239558511"
                rpy="2.52462250363 -0.387794511771 0.0912924111683"/>
        <parent link="l_forearm"/>
        <child link="l_forearm_skin_14"/>
        <dynamics damping="0.1"/>
    </joint>
    <link name="l_forearm_skin_15"/>
    <joint name="l_forearm_skin_15_fixed_joint" type="fixed">
        <origin xyz="0.0633786419662 -0.0293843 -0.00879405455544"
                rpy="1.80492769741 -0.289783281916 0.113933739306"/>
        <parent link="l_forearm"/>
        <child link="l_forearm_skin_15"/>
        <dynamics damping="0.1"/>
    </joint>
    <link name="l_forearm_skin_16"/>
    <joint name="l_forearm_skin_16_fixed_joint" type="fixed">
        <origin xyz="0.03792482187 -0.0327268 0.0206369503605"
                rpy="1.41280007026 -0.25082462139 0.0758652301584"/>
        <parent link="l_forearm"/>
        <child link="l_forearm_skin_16"/>
        <dynamics damping="0.1"/>
    </joint>
    <link name="l_forearm_skin_17"/>
    <joint name="l_forearm_skin_17_fixed_joint" type="fixed">
        <origin xyz="0.0543170548821 -0.0299646 0.0303291240179"
                rpy="1.27223716205 -0.23059304703 0.109637225219"/>
        <parent link="l_forearm"/>
        <child link="l_forearm_skin_17"/>
        <dynamics damping="0.1"/>
    </joint>
    <link name="l_forearm_skin_19"/>
    <joint name="l_forearm_skin_19_fixed_joint" type="fixed">
        <origin xyz="0.0381266107138 0.029054 0.020690605393"
                rpy="-1.41560888703 -0.252569290226 -0.0644404747027"/>
        <parent link="l_forearm"/>
        <child link="l_forearm_skin_19"/>
        <dynamics damping="0.1"/>
    </joint>
    <link name="l_forearm_skin_22"/>
    <joint name="l_forearm_skin_22_fixed_joint" type="fixed">
        <origin xyz="0.0544173950421 0.026483 0.0306037516609"
                rpy="-1.2658242728 -0.234328151379 -0.0937094738802"/>
        <parent link="l_forearm"/>
        <child link="l_forearm_skin_22"/>
        <dynamics damping="0.1"/>
    </joint>
    <link name="l_forearm_skin_24"/>
    <joint name="l_forearm_skin_24_fixed_joint" type="fixed">
        <origin xyz="0.0700345319564 0.007477 0.050069108714"
                rpy="-0.23489327644 -0.0388172993982 -0.0548291989999"/>
        <parent link="l_forearm"/>
        <child link="l_forearm_skin_24"/>
        <dynamics damping="0.1"/>
    </joint>
    <link name="l_forearm_skin_25"/>
    <joint name="l_forearm_skin_25_fixed_joint" type="fixed">
        <origin xyz="0.0535999216295 0.015984 0.0454698125045"
                rpy="-0.564295527715 -0.136980272197 -0.0819608256656"/>
        <parent link="l_forearm"/>
        <child link="l_forearm_skin_25"/>
        <dynamics damping="0.1"/>
    </joint>
    <link name="l_forearm_skin_28"/>
    <joint name="l_forearm_skin_28_fixed_joint" type="fixed">
        <origin xyz="0.0535859272148 -0.0196522 0.045352037397"
                rpy="0.579311106949 -0.133994306778 0.0867597858312"/>
        <parent link="l_forearm"/>
        <child link="l_forearm_skin_28"/>
        <dynamics damping="0.1"/>
    </joint>
    <link name="l_forearm_skin_29"/>
    <joint name="l_forearm_skin_29_fixed_joint" type="fixed">
        <origin xyz="0.0700355805031 -0.0111936 0.0500111036233"
                rpy="0.248630982209 -0.0383136556786 0.0583026624266"/>
        <parent link="l_forearm"/>
        <child link="l_forearm_skin_29"/>
        <dynamics damping="0.1"/>
    </joint>
    <link name="l_forearm_dh_frame"/>
    <joint name="l_forearm_dh_frame_fixed_joint" type="fixed">
        <origin xyz="0.102871102373 7.00000000002e-06 0.0275642213111"
                rpy="2.87979333376 0 1.57079632679"/>
        <parent link="l_forearm"/>
        <child link="l_forearm_dh_frame"/>
        <dynamics damping="0.1"/>
    </joint>
    <link name="l_wrist_1">
        <inertial>
            <origin xyz="-0.000981313804428 -0.001178 0.00408345773913" rpy="0 0 0"/>
            <mass value="0.0362152"/>
            <inertia ixx="0.01" ixy="3.08362e-08" ixz="9.42153e-07" iyy="0.01"
                     iyz="-1.58924e-07" izz="0.01"/>
        </inertial>
        <visual>
            <origin xyz="-0.400314530555 -7.00000000009e-06 -0.105038082269" rpy="0 0 0"/>
            <geometry>
                <mesh filename="package://iCub/meshes/simmechanics/sim_sea_2-5_l_wrist_pitch_prt-binary.stl"
                      scale="0.001 0.001 0.001"/>
            </geometry>
            <material name="dgreen">
                <color rgba="0.1 0.8 0.1 1"/>
            </material>
        </visual>
        <collision>
            <origin xyz="-0.400314530555 -7.00000000009e-06 -0.105038082269" rpy="0 0 0"/>
            <geometry>
                <mesh filename="package://iCub/meshes/simmechanics/sim_sea_2-5_l_wrist_pitch_prt-binary.stl"
                      scale="0.001 0.001 0.001"/>
            </geometry>
        </collision>
    </link>
    <joint name="l_wrist_pitch" type="revolute">
        <origin xyz="0.103427563179 7.00000000002e-06 0.0254874807467" rpy="0 0 0"/>
        <axis xyz="0.258818979447 0.0 -0.965925843882"/>
        <parent link="l_forearm"/>
        <child link="l_wrist_1"/>
        <limit effort="50000" lower="-1.3962634016" upper="0.436332312999"
               velocity="50000"/>
        <dynamics damping="1.0" friction="0.0"/>
    </joint>
    <link name="l_hand">
        <inertial>
            <origin xyz="0.0647680204057 0.0056304 0.0226602208449" rpy="0 0 0"/>
            <mass value="0.247806"/>
            <inertia ixx="0.01" ixy="2.96453e-06" ixz="-3.68906e-05" iyy="0.01"
                     iyz="2.06885e-05" izz="0.01"/>
        </inertial>
        <visual>
            <origin xyz="-0.399680424055 0.0194929 -0.107404600587" rpy="0 0 0"/>
            <geometry>
                <mesh filename="package://iCub/meshes/simmechanics/sim_sea_2-5_l_hand_prt-binary.stl"
                      scale="0.001 0.001 0.001"/>
            </geometry>
            <material name="gray">
                <color rgba="0.5 0.5 0.5 1"/>
            </material>
        </visual>
        <collision>
            <origin xyz="-0.399680424055 0.0194929 -0.107404600587" rpy="0 0 0"/>
            <geometry>
                <mesh filename="package://iCub/meshes/simmechanics/sim_sea_2-5_l_hand_prt-binary.stl"
                      scale="0.001 0.001 0.001"/>
            </geometry>
        </collision>
    </link>
    <joint name="l_wrist_yaw" type="revolute">
        <origin xyz="-0.000634106499644 -0.0194999 0.00236651831751" rpy="0 0 0"/>
        <axis xyz="-2.22044604925e-16 1.0 0.0"/>
        <parent link="l_wrist_1"/>
        <child link="l_hand"/>
        <limit effort="50000" lower="-0.349065850399" upper="0.436332312999"
               velocity="50000"/>
        <dynamics damping="1.0" friction="0.0"/>
    </joint>
    <link name="l_hand_dh_frame"/>
    <joint name="l_hand_dh_frame_fixed_joint" type="fixed">
        <origin xyz="0.0576542978428 -0.0055568 0.0136938323083"
                rpy="-1.57079632679 -0.261799319827 0"/>
        <parent link="l_hand"/>
        <child link="l_hand_dh_frame"/>
        <dynamics damping="0.1"/>
    </joint>
    <link name="neck_1">
        <inertial>
            <origin xyz="0.0143705608 0.006567 -0.0063842" rpy="0 0 0"/>
            <mass value="0.125793"/>
            <inertia ixx="0.01" ixy="8.09156e-08" ixz="-3.74998e-08" iyy="0.01"
                     iyz="9.39717e-06" izz="0.01"/>
        </inertial>
        <visual>
            <origin xyz="0.0142999998093 -0.079997 -0.0295008" rpy="0 0 0"/>
            <geometry>
                <mesh filename="package://iCub/meshes/simmechanics/sim_sea_2-5_neck_1_prt-binary.stl"
                      scale="0.001 0.001 0.001"/>
            </geometry>
            <material name="green">
                <color rgba="0 1 0 1"/>
            </material>
        </visual>
        <collision>
            <origin xyz="0.0142999998093 -0.079997 -0.0295008" rpy="0 0 0"/>
            <geometry>
                <mesh filename="package://iCub/meshes/simmechanics/sim_sea_2-5_neck_1_prt-binary.stl"
                      scale="0.001 0.001 0.001"/>
            </geometry>
        </collision>
    </link>
    <joint name="neck_pitch" type="revolute">
        <origin xyz="-0.0142999998093 0.172797 0.0053118" rpy="0 0 0"/>
        <axis xyz="-1.0 0.0 0.0"/>
        <parent link="chest"/>
        <child link="neck_1"/>
        <limit effort="50000" lower="-0.698131700798" upper="0.383972435439"
               velocity="50000"/>
        <dynamics damping="1.0" friction="0.0"/>
    </joint>
    <link name="neck_2">
        <inertial>
            <origin xyz="-8.8573009265e-05 0.035225 -0.01954527" rpy="0 0 0"/>
            <mass value="0.177087"/>
            <inertia ixx="0.01" ixy="-5.25591e-07" ixz="4.68307e-07" iyy="0.01"
                     iyz="9.81476e-06" izz="0.01"/>
        </inertial>
        <visual>
            <origin xyz="0 -0.089497 -0.05030077" rpy="0 0 0"/>
            <geometry>
                <mesh filename="package://iCub/meshes/simmechanics/sim_sea_2-5_neck_2_prt-binary.stl"
                      scale="0.001 0.001 0.001"/>
            </geometry>
            <material name="black">
                <color rgba="0 0 0 1"/>
            </material>
        </visual>
        <collision>
            <origin xyz="0 -0.089497 -0.05030077" rpy="0 0 0"/>
            <geometry>
                <mesh filename="package://iCub/meshes/simmechanics/sim_sea_2-5_neck_2_prt-binary.stl"
                      scale="0.001 0.001 0.001"/>
            </geometry>
        </collision>
    </link>
    <joint name="neck_roll" type="revolute">
        <origin xyz="0.0142999998093 0.0095 0.02079997" rpy="0 0 0"/>
        <axis xyz="0.0 0.0 1.0"/>
        <parent link="neck_1"/>
        <child link="neck_2"/>
        <limit effort="50000" lower="-0.349065850399" upper="0.349065850399"
               velocity="50000"/>
        <dynamics damping="1.0" friction="0.0"/>
    </joint>
    <link name="head">
        <inertial>
            <origin xyz="-0.000574157809265 0.113511 -0.0075392" rpy="0 0 0"/>
            <mass value="1.50691"/>
            <inertia ixx="0.00680478" ixy="-1.60267e-05" ixz="7.28166e-05"
                     iyy="0.00634736" iyz="0.000292091" izz="0.00478116"/>
        </inertial>
        <visual>
            <origin xyz="0 -0.067153 -0.0295008" rpy="0 0 0"/>
            <geometry>
                <mesh filename="package://iCub/meshes/simmechanics/sim_sea_2-5_head_prt-binary.stl"
                      scale="0.001 0.001 0.001"/>
            </geometry>
            <material name="red">
                <color rgba="1 0 0 1"/>
            </material>
        </visual>
        <collision>
            <origin xyz="0 -0.067153 -0.0295008" rpy="0 0 0"/>
            <geometry>
                <mesh filename="package://iCub/meshes/simmechanics/sim_sea_2-5_head_prt-binary.stl"
                      scale="0.001 0.001 0.001"/>
            </geometry>
        </collision>
    </link>
    <joint name="neck_yaw" type="revolute">
        <origin xyz="0 -0.022344 -0.02079997" rpy="0 0 0"/>
        <axis xyz="0.0 1.0 0.0"/>
        <parent link="neck_2"/>
        <child link="head"/>
        <limit effort="50000" lower="-0.872664625997" upper="0.872664625997"
               velocity="50000"/>
        <dynamics damping="1.0" friction="0.0"/>
    </joint>
    <link name="base_link"/>
    <joint name="base_fixed_joint" type="fixed">
        <origin xyz="0 0 0" rpy="0 -0 0"/>
        <axis xyz="0 0 0"/>
        <parent link="base_link"/>
        <child link="root_link"/>
    </joint>
    <link name="l_foot_dh_frame"/>
    <joint name="l_foot_dh_frame_fixed_joint" type="fixed">
        <origin xyz="0.0 0 0.004" rpy="0 1.5708 0"/>
        <axis xyz="0 0 0"/>
        <parent link="l_foot"/>
        <child link="l_foot_dh_frame"/>
    </joint>
    <link name="r_foot_dh_frame"/>
    <joint name="r_foot_dh_frame_fixed_joint" type="fixed">
        <origin xyz="0.0 0 0.004" rpy="0 1.5708 0"/>
        <axis xyz="0 0 0"/>
        <parent link="r_foot"/>
        <child link="r_foot_dh_frame"/>
    </joint>
    <gazebo reference="l_foot">
        <collision>
            <surface>
                <bounce>
                    <restitution_coefficient>0</restitution_coefficient>
                    <threshold>100000</threshold>
                </bounce>
            </surface>
        </collision>
        <maxContacts>4</maxContacts>
        <kp>18000000</kp>
        <kd>100</kd>
        <maxVel>100</maxVel>
        <minDepth>0.0001</minDepth>
        <mu1>1</mu1>
        <mu2>1</mu2>
        <fdir1>0 0 0</fdir1>
    </gazebo>
    <gazebo reference="r_foot">
        <collision>
            <surface>
                <bounce>
                    <restitution_coefficient>0</restitution_coefficient>
                    <threshold>100000</threshold>
                </bounce>
            </surface>
        </collision>
        <maxContacts>4</maxContacts>
        <kp>18000000</kp>
        <kd>100</kd>
        <maxVel>100</maxVel>
        <minDepth>0.0001</minDepth>
        <mu1>1</mu1>
        <mu2>1</mu2>
        <fdir1>0 0 0</fdir1>
    </gazebo>
    <gazebo reference="r_hip_pitch">
        <implicitSpringDamper>1</implicitSpringDamper>
    </gazebo>
    <gazebo reference="r_hip_roll">
        <implicitSpringDamper>1</implicitSpringDamper>
    </gazebo>
    <gazebo reference="r_hip_yaw">
        <implicitSpringDamper>1</implicitSpringDamper>
    </gazebo>
    <gazebo reference="r_knee">
        <implicitSpringDamper>1</implicitSpringDamper>
    </gazebo>
    <gazebo reference="r_ankle_pitch">
        <implicitSpringDamper>1</implicitSpringDamper>
    </gazebo>
    <gazebo reference="r_ankle_roll">
        <implicitSpringDamper>1</implicitSpringDamper>
    </gazebo>
    <gazebo reference="l_hip_pitch">
        <implicitSpringDamper>1</implicitSpringDamper>
    </gazebo>
    <gazebo reference="l_hip_roll">
        <implicitSpringDamper>1</implicitSpringDamper>
    </gazebo>
    <gazebo reference="l_hip_yaw">
        <implicitSpringDamper>1</implicitSpringDamper>
    </gazebo>
    <gazebo reference="l_knee">
        <implicitSpringDamper>1</implicitSpringDamper>
    </gazebo>
    <gazebo reference="l_ankle_pitch">
        <implicitSpringDamper>1</implicitSpringDamper>
    </gazebo>
    <gazebo reference="l_ankle_roll">
        <implicitSpringDamper>1</implicitSpringDamper>
    </gazebo>
    <gazebo reference="torso_pitch">
        <implicitSpringDamper>1</implicitSpringDamper>
    </gazebo>
    <gazebo reference="torso_roll">
        <implicitSpringDamper>1</implicitSpringDamper>
    </gazebo>
    <gazebo reference="torso_yaw">
        <implicitSpringDamper>1</implicitSpringDamper>
    </gazebo>
    <gazebo reference="r_shoulder_pitch">
        <implicitSpringDamper>1</implicitSpringDamper>
    </gazebo>
    <gazebo reference="r_shoulder_roll">
        <implicitSpringDamper>1</implicitSpringDamper>
    </gazebo>
    <gazebo reference="r_shoulder_yaw">
        <implicitSpringDamper>1</implicitSpringDamper>
    </gazebo>
    <gazebo reference="r_elbow">
        <implicitSpringDamper>1</implicitSpringDamper>
    </gazebo>
    <gazebo reference="r_wrist_prosup">
        <implicitSpringDamper>1</implicitSpringDamper>
    </gazebo>
    <gazebo reference="r_wrist_pitch">
        <implicitSpringDamper>1</implicitSpringDamper>
    </gazebo>
    <gazebo reference="r_wrist_yaw">
        <implicitSpringDamper>1</implicitSpringDamper>
    </gazebo>
    <gazebo reference="l_shoulder_pitch">
        <implicitSpringDamper>1</implicitSpringDamper>
    </gazebo>
    <gazebo reference="l_shoulder_roll">
        <implicitSpringDamper>1</implicitSpringDamper>
    </gazebo>
    <gazebo reference="l_shoulder_yaw">
        <implicitSpringDamper>1</implicitSpringDamper>
    </gazebo>
    <gazebo reference="l_elbow">
        <implicitSpringDamper>1</implicitSpringDamper>
    </gazebo>
    <gazebo reference="l_wrist_prosup">
        <implicitSpringDamper>1</implicitSpringDamper>
    </gazebo>
    <gazebo reference="l_wrist_pitch">
        <implicitSpringDamper>1</implicitSpringDamper>
    </gazebo>
    <gazebo reference="l_wrist_yaw">
        <implicitSpringDamper>1</implicitSpringDamper>
    </gazebo>
    <gazebo reference="neck_pitch">
        <implicitSpringDamper>1</implicitSpringDamper>
    </gazebo>
    <gazebo reference="neck_roll">
        <implicitSpringDamper>1</implicitSpringDamper>
    </gazebo>
    <gazebo reference="neck_yaw">
        <implicitSpringDamper>1</implicitSpringDamper>
    </gazebo>
    <gazebo>
        <pose>0.0 0.0 0.63 0.0 0.0 3.14</pose>
    </gazebo>
</robot>
